Workbook

Sheet Ф200
A1: КСС - Обособена позиция № 2: „Реконструкция на водопровод ул. Камчия с. Близнаци о.т.15-14а-12-36-34-41-42-38-37-61-64-84-82-80-93 общ. Аврен, обл. Варна“
A2: N | C2: НАИМЕНОВАНИЕ НА РАБОТИТЕ | D2: мярка | E2: КОЛИЧ. | F2: Ед.цена | G2: Обща ст-ст | J2: КОЛИЧ.
A3: Водопровод Ф200
A4: 1. Подготовка на строителната площадка
A5: 1 | B5: Анализ 1 | C5: Рязане на асфалтова настилка | D5: лин.м. | E5: 1290.5 | F5: ='Ед. Цени'!E4 -> 1.51 | G5: =ROUND(E5*F5,2) -> 1948.66 | J5: 1290.5 | K5: =E5-J5 -> 0
A6: 2 | B6: Анализ 2 | C6: Разваляне на съществуваща асфалтова настилка | D6: м3 | E6: 65.02 | F6: ='Ед. Цени'!E5 -> 1.65 | G6: =ROUND(E6*F6,2) -> 107.28 | J6: 65.02 | K6: =E6-J6 -> 0
A7: 3 | B7: Анализ 3 | C7: Разваляне на трошенокаменна настилка | D7: м3 | E7: 406.36 | F7: ='Ед. Цени'!E6 -> 1.38 | G7: =ROUND(E7*F7,2) -> 560.78 | J7: 406.36 | K7: =E7-J7 -> 0
A8: 4 | C8: Изкоп общо: | E8: 806.49 | J8: 806.49 | K8: =E8-J8 -> 0
A9: 5 | B9: Анализ 5 | C9: Механизиран изкоп- 75% - земна почва | D9: м3 | E9: 604.87 | F9: ='Ед. Цени'!E8 -> 6.5 | G9: =ROUND(E9*F9,2) -> 3931.66 | J9: 604.87 | K9: =E9-J9 -> 0
A10: 6 | B10: Анализ 6 | C10: Ръчен изкоп- 15% - земна почва | D10: м3 | E10: 120.98 | F10: ='Ед. Цени'!E9 -> 12.28 | G10: =ROUND(E10*F10,2) -> 1485.63 | J10: 120.98 | K10: =E10-J10 -> 0
A11: 7 | B11: Анализ 7 | C11: Изкоп с къртач- 10% - скална почва | D11: м3 | E11: 80.65 | F11: ='Ед. Цени'!E10 -> 20.68 | G11: =ROUND(E11*F11,2) -> 1667.84 | J11: 80.65 | K11: =E11-J11 -> 0
A12: 8 | B12: Анализ 8 | C12: Прехвърляне до 3м хор. или 2м верт. Разстояние ръчно, земни почви | D12: м3 | E12: 135.17 | F12: ='Ед. Цени'!E11 -> 4 | G12: =ROUND(E12*F12,2) -> 540.68 | J12: 135.17 | K12: =E12-J12 -> 0
A13: 9 | B13: Анализ 9 | C13: Неплътно укрепване и разкрепване на изкоп | D13: m² | E13: 2125.12 | F13: ='Ед. Цени'!E12 -> 1.86 | G13: =ROUND(E13*F13,2) -> 3952.72 | J13: 2125.12 | K13: =E13-J13 -> 0
A14: 10 | B14: Анализ 10 | C14: Направа на подложно легло от пясък- 10см | D14: м3 | E14: 67.35 | F14: ='Ед. Цени'!E13 -> 31.11 | G14: =ROUND(E14*F14,2) -> 2095.26 | J14: 67.35 | K14: =E14-J14 -> 0
A15: 11 | B15: Анализ 11 | C15: Доставка и полагане на полиетиленова сигнална лента | D15: лин.м. | E15: 645.25 | F15: ='Ед. Цени'!E14 -> 0.56 | G15: =ROUND(E15*F15,2) -> 361.34 | J15: 645.25 | K15: =E15-J15 -> 0
K16: =E16-J16 -> 0
A17: 2. МОНТАЖНА ЧАСТ Ф 200 | K17: =E17-J17 -> 0
A18: 12 | B18: Анализ 12 | C18: Доставка и монтаж на полиетиленови тръби с висока плътност /ПЕВП/ ø200, PN 10, в изкоп | D18: лин.м. | E18: 464 | F18: ='Ед. Цени'!E15 -> 40.87 | G18: =ROUND(E18*F18,2) -> 18963.68 | J18: 464 | K18: =E18-J18 -> 0
A19: 13 | B19: Анализ 13 | C19: Заварки към ПЕВП тръби Ф200 | D19: бр. | E19: 74 | F19: ='Ед. Цени'!E16 -> 7.85 | G19: =ROUND(E19*F19,2) -> 580.9 | J19: 74 | K19: =E19-J19 -> 0
A20: 14 | B20: Анализ 14 | C20: Доставка и монтаж на шибър PN10 Dn200 с охранителна гарнитура | D20: бр. | E20: 1 | F20: ='Ед. Цени'!E17 -> 270.01 | G20: =ROUND(E20*F20,2) -> 270.01 | J20: 1 | K20: =E20-J20 -> 0
A21: 15 | B21: Анализ 15 | C21: Доставка и монтаж на полиет. фланшов накрайник ø200 | D21: бр. | E21: 1 | F21: ='Ед. Цени'!E18 -> 65.27 | G21: =ROUND(E21*F21,2) -> 65.27 | J21: 1 | K21: =E21-J21 -> 0
A22: 16 | B22: Анализ 16 | C22: Доставка и монтаж на свободен фланец OD200/Dn200 PN10 | D22: бр. | E22: 1 | F22: ='Ед. Цени'!E19 -> 59.52 | G22: =ROUND(E22*F22,2) -> 59.52 | J22: 1 | K22: =E22-J22 -> 0
A23: 17 | B23: Анализ 17 | C23: Доставка и монтаж на HDPE коляно PN10 ∅200-30⁰ | D23: бр. | E23: 1 | F23: ='Ед. Цени'!E20 -> 64.14 | G23: =ROUND(E23*F23,2) -> 64.14 | J23: 1 | K23: =E23-J23 -> 0
A24: 18 | B24: Анализ 18 | C24: Доставка и монтаж на HDPE тройник PN10 ∅200-90 | D24: бр. | E24: 8 | F24: ='Ед. Цени'!E21 -> 86.22 | G24: =ROUND(E24*F24,2) -> 689.76 | J24: 8 | K24: =E24-J24 -> 0
A25: 19 | B25: Анализ 19 | C25: Заварки към ПЕВП 200 | D25: бр | E25: 78 | F25: ='Ед. Цени'!E22 -> 7.85 | G25: =ROUND(E25*F25,2) -> 612.3 | J25: 78 | K25: =E25-J25 -> 0
A26: 20 | B26: Анализ 20 | C26: опорен блок | D26: бр. | E26: 12 | F26: ='Ед. Цени'!E23 -> 20 | G26: =ROUND(E26*F26,2) -> 240 | J26: 12 | K26: =E26-J26 -> 0
A27: 3. Шахта реголатор налягане | K27: =E27-J27 -> 0
A28: 21 | B28: Анализ 21 | C28: Доставка и полагане на подложен бетон С 12/15 | D28: м3 | E28: 0.8 | F28: ='Ед. Цени'!E24 -> 115.81 | G28: =ROUND(E28*F28,2) -> 92.65 | J28: 0.8 | K28: =E28-J28 -> 0
A29: 22 | B29: Анализ 22 | C29: Доставка и монтаж на армировка | D29: кг | E29: 17.49 | F29: ='Ед. Цени'!E25 -> 2.86 | G29: =ROUND(E29*F29,2) -> 50.02 | J29: 17.49 | K29: =E29-J29 -> 0
A30: 23 | B30: Анализ 23 | C30: Трошен камък- дренажна призма | D30: м3 | E30: 1 | F30: ='Ед. Цени'!E26 -> 29.9 | G30: =ROUND(E30*F30,2) -> 29.9 | J30: 1 | K30: =E30-J30 -> 0
A31: 24 | B31: Анализ 24 | C31: Пясък- дренажна призма | D31: м3 | E31: 1 | F31: ='Ед. Цени'!E27 -> 31.11 | G31: =ROUND(E31*F31,2) -> 31.11 | J31: 1 | K31: =E31-J31 -> 0
A32: 25 | B32: Анализ 25 | C32: Доставка и монтаж филтър Dn 100 | D32: бр. | E32: 1 | F32: ='Ед. Цени'!E28 -> 173.21 | G32: =ROUND(E32*F32,2) -> 173.21 | J32: 1 | K32: =E32-J32 -> 0
A33: 26 | B33: Анализ 26 | C33: Доставка и монтаж на HDPE тройник PN10 ∅200-160 | D33: бр. | E33: 1 | F33: ='Ед. Цени'!E29 -> 91.06 | G33: =ROUND(E33*F33,2) -> 91.06 | J33: 1 | K33: =E33-J33 -> 0
A34: 27 | B34: Анализ 27 | C34: Доставка и монтаж на HDPE намалител PN10 ∅200-125 | D34: бр. | E34: 1 | F34: ='Ед. Цени'!E30 -> 66.86 | G34: =ROUND(E34*F34,2) -> 66.86 | J34: 1 | K34: =E34-J34 -> 0
A35: 28 | B35: Анализ 28 | C35: Доставка и монтаж наHDPE коляно PN10 ∅160-90⁰ | D35: бр. | E35: 1 | F35: ='Ед. Цени'!E31 -> 59.3 | G35: =ROUND(E35*F35,2) -> 59.3 | J35: 1 | K35: =E35-J35 -> 0
A36: 29 | B36: Анализ 29 | C36: Доставка и монтаж на шибър PN10 Dn150 | D36: бр. | E36: 1 | F36: ='Ед. Цени'!E32 -> 190.15 | G36: =ROUND(E36*F36,2) -> 190.15 | J36: 1 | K36: =E36-J36 -> 0
A37: 30 | B37: Анализ 30 | C37: Доставка и монтаж на шибър PN10 Dn100 | D37: бр. | E37: 2 | F37: ='Ед. Цени'!E33 -> 159.9 | G37: =ROUND(E37*F37,2) -> 319.8 | J37: 2 | K37: =E37-J37 -> 0
A38: 31 | B38: Анализ 31 | C38: Доставка и монтаж на полиет. фланшов накрайник ø125 | D38: бр. | E38: 2 | F38: ='Ед. Цени'!E34 -> 53.17 | G38: =ROUND(E38*F38,2) -> 106.34 | J38: 2 | K38: =E38-J38 -> 0
A39: 32 | B39: Анализ 32 | C39: Доставка и монтаж на свободен фланец OD125/Dn100 PN16 | D39: бр. | E39: 2 | F39: ='Ед. Цени'!E35 -> 44.76 | G39: =ROUND(E39*F39,2) -> 89.52 | J39: 2 | K39: =E39-J39 -> 0
... A56: 49 | B56: Анализ 49 | C56: Доставка и полагане на чугунен капак D400 | D56: бр | E56: 1 | F56: ='Ед. Цени'!E52 -> 146.73 | G56: =ROUND(E56*F56,2) -> 146.73 | J56: 1 | K56: =E56-J56 -> 0
...

Sheet Ф160
A1: Обект: Реконструкция водопровод ул. Камчия с. Близнация о.т. 15-14а-12-36-34-41-42-38-37-61-64-84-82-80-90
A3: N | C3: НАИМЕНОВАНИЕ НА РАБОТИТЕ | D3: мярка | E3: КОЛИЧ. | F3: Ед.цена | G3: Обща ст-ст | J3: КОЛИЧ.
A4: Водопровод Ф160
A5: 1. Подготовка на строителната площадка
A6: 1 | B6: Анализ 1 | C6: Рязане на асфалтова настилка | D6: лин.м. | E6: 1214 | F6: ='Ед. Цени'!E4 -> 1.51 | G6: =ROUND(E6*F6,2) -> 1833.14 | J6: 1214
A7: 2 | B7: Анализ 2 | C7: Разваляне на съществуваща асфалтова настилка | D7: м3 | E7: 46.62 | F7: ='Ед. Цени'!E5 -> 1.65 | G7: =ROUND(E7*F7,2) -> 76.92 | J7: 46.62
A8: 3 | B8: Анализ 3 | C8: Разваляне на трошенокаменна настилка | D8: м3 | E8: 291.36 | F8: ='Ед. Цени'!E6 -> 1.38 | G8: =ROUND(E8*F8,2) -> 402.08 | J8: 291.36
A9: 4 | C9: Изкоп общо: | E9: 767.01 | J9: 767.01
A10: 5 | B10: Анализ 5 | C10: Механизиран изкоп- 75% - земна почва | D10: м3 | E10: 575.25 | F10: ='Ед. Цени'!E8 -> 6.5 | G10: =ROUND(E10*F10,2) -> 3739.13 | J10: 575.25
A11: 6 | B11: Анализ 6 | C11: Ръчен изкоп- 15% - земна почва | D11: м3 | E11: 115.05 | F11: ='Ед. Цени'!E9 -> 12.28 | G11: =ROUND(E11*F11,2) -> 1412.81 | J11: 115.05
A12: 7 | B12: Анализ 7 | C12: Изкоп с къртач- 10%- скална почва | D12: м3 | E12: 76.7 | F12: ='Ед. Цени'!E10 -> 20.68 | G12: =ROUND(E12*F12,2) -> 1586.16 | J12: 76.7
A13: 8 | B13: Анализ 8 | C13: Прехвърляне до 3м хор. или 2м верт. Разстояние ръчно, земни почви | D13: м3 | E13: 115.05 | F13: ='Ед. Цени'!E11 -> 4 | G13: =ROUND(E13*F13,2) -> 460.2 | J13: 115.05
A14: 9 | B14: Анализ 9 | C14: Неплътно укрепване и разкрепване на изкоп | D14: m² | E14: 2780.06 | F14: ='Ед. Цени'!E12 -> 1.86 | G14: =ROUND(E14*F14,2) -> 5170.91 | J14: 2780.06
A15: 10 | B15: Анализ 10 | C15: Направа на подложно легло от пясък- 10см | D15: м3 | E15: 49.17 | F15: ='Ед. Цени'!E13 -> 31.11 | G15: =ROUND(E15*F15,2) -> 1529.68 | J15: 49.17
A16: 11 | B16: Анализ 11 | C16: Доставка и полагане на полиетиленова сигнална лента | D16: лин.м. | E16: 607 | F16: ='Ед. Цени'!E14 -> 0.56 | G16: =ROUND(E16*F16,2) -> 339.92 | J16: 607
A17: 2. МОНТАЖНА ЧАСТ
A18: 12 | B18: Анализ 66 | C18: Доставка и монтаж на полиетиленови тръби с висока плътност /ПЕВП/ ø160, PN 16, в изкоп | D18: лин.м. | E18: 607 | F18: ='Ед. Цени'!E69 -> 45.22 | G18: =ROUND(E18*F18,2) -> 27448.54 | J18: 607
A19: 13 | B19: Анализ 67 | C19: Заварки към ПЕВП тръби Ф160 | D19: бр. | E19: 102 | F19: ='Ед. Цени'!E70 -> 7.19 | G19: =ROUND(E19*F19,2) -> 733.38 | J19: 102
A20: 14 | B20: Анализ 68 | C20: Доставка и монтаж на шибър PN16 Dn150 с охранителна гарнитура | D20: бр. | E20: 1 | F20: ='Ед. Цени'!E71 -> 205.88 | G20: =ROUND(E20*F20,2) -> 205.88 | J20: 1
A21: 15 | B21: Анализ 33 | C21: Доставка и монтаж на полиет. фланшов накрайник ø160 | D21: бр. | E21: 2 | F21: ='Ед. Цени'!E36 -> 58.86 | G21: =ROUND(E21*F21,2) -> 117.72 | J21: 2
A22: 16 | B22: Анализ 34 | C22: Доставка и монтаж на свободен фланец OD160/Dn150 PN16 | D22: бр. | E22: 2 | F22: ='Ед. Цени'!E37 -> 49.72 | G22: =ROUND(E22*F22,2) -> 99.44 | J22: 2
A23: 17 | B23: Анализ 69 | C23: Доставка и монтаж на универсалeн фланшов адаптор ∅160-150 | D23: бр. | E23: 1 | F23: ='Ед. Цени'!E72 -> 118.2 | G23: =ROUND(E23*F23,2) -> 118.2 | J23: 1
A24: 18 | B24: Анализ 70 | C24: Доставка и монтаж на универсалeн адаптор ∅150 | D24: бр. | E24: 1 | F24: ='Ед. Цени'!E73 -> 118.2 | G24: =ROUND(E24*F24,2) -> 118.2 | J24: 1
A25: 19 | B25: Анализ 71 | C25: Заварки към ПЕВП 160 | D25: бр | E25: 45 | F25: ='Ед. Цени'!E74 -> 7.19 | G25: =ROUND(E25*F25,2) -> 323.55 | J25: 45
A26: 20 | B26: Анализ 20 | C26: опорен блок | D26: бр. | E26: 20 | F26: ='Ед. Цени'!E23 -> 20 | G26: =ROUND(E26*F26,2) -> 400 | J26: 20
A27: 3. Обратно засипване и възстановяване на настилки
A28: 21 | B28: Анализ 55 | C28: Обратен насип от пясък | D28: м3 | E28: 654.19 | F28: ='Ед. Цени'!E58 -> 31.11 | G28: =ROUND(E28*F28,2) -> 20351.85 | J28: 654.19
A29: 22 | B29: Анализ 56 | C29: Уплътняване с пневм. трамбовка през 20 см. | D29: м3 | E29: 654.19 | F29: ='Ед. Цени'!E59 -> 4 | G29: =ROUND(E29*F29,2) -> 2616.76 | J29: 654.19
A30: 23 | B30: Анализ 57 | C30: Възтановяване на основа от едро трошени камъни 35cm | D30: м3 | E30: 172.08 | F30: ='Ед. Цени'!E60 -> 31.11 | G30: =ROUND(E30*F30,2) -> 5353.41 | J30: 172.08
A31: 24 | B31: Анализ 58 | C31: Възтановяване на трошенокаменна настилка.15cm | D31: м3 | E31: 73.75 | F31: ='Ед. Цени'!E61 -> 31.11 | G31: =ROUND(E31*F31,2) -> 2294.36 | J31: 73.75
A32: 25 | B32: Анализ 59 | C32: Доставка и полагане на неплътен асфалтобетон за изравнителен пласт с дебелина в уплътнено състояние 4см | D32: тон | E32: 55.94 | F32: ='Ед. Цени'!E62 -> 125.82 | G32: =ROUND(E32*F32,2) -> 7038.37 | J32: 55.94
A33: 26 | B33: Анализ 60 | C33: Доставка и полагане на плътен асфалтобетон за износващ пласт с дебелина в уплътнено състояние 4см | D33: тон | E33: 55.94 | F33: ='Ед. Цени'!E63 -> 129.45 | G33: =ROUND(E33*F33,2) -> 7241.43 | J33: 55.94
A34: 27 | B34: Анализ 61 | C34: Натоварване на земни маси и извозването им до временно депо | D34: м3 | E34: 1058.36 | F34: ='Ед. Цени'!E64 -> 3.78 | G34: =ROUND(E34*F34,2) -> 4000.6 | J34: 1058.36
A35: 28 | B35: Анализ 62 | C35: Разриване на земни маси на депо | D35: м3 | E35: 1058.36 | F35: ='Ед. Цени'!E65 -> 2.48 | G35: =ROUND(E35*F35,2) -> 2624.73 | J35: 1058.36
A36: 29 | B36: Анализ 63 | C36: Натоварване на строителни отпадъци и извозването им на до 15км | D36: м3/км | E36: 699.3 | F36: ='Ед. Цени'!E66 -> 6.53 | G36: =ROUND(E36*F36,2) -> 4566.43 | J36: 699.3
A37: 4. Дезинфекция и изпитване
A38: 30 | B38: Анализ 64 | C38: Дезинфекция на водопровода | D38: m | E38: 607 | F38: ='Ед. Цени'!E67 -> 1.36 | G38: =ROUND(E38*F38,2) -> 825.52 | J38: 607
A39: 31 | B39: Анализ 65 | C39: Изпитване на водопровода | D39: m | E39: 607 | F39: ='Ед. Цени'!E68 -> 1.49 | G39: =ROUND(E39*F39,2) -> 904.43 | J39: 607
G40: =SUM(G6:G39) -> 103933.75
G41: =0.2*G40 -> 20786.75
...

Sheet Ф 125
A1: Обект: Реконструкция водопровод ул. Камчия с. Близнация о.т. 15-14а-12-36-34-41-42-38-37-61-64-84-82-80-90
A3: N | C3: НАИМЕНОВАНИЕ НА РАБОТИТЕ | D3: мярка | E3: КОЛИЧ. | F3: Ед.цена | G3: Обща ст-ст | J3: КОЛИЧ.
A4: Водопровод Ф125
A5: 1. Подготовка на строителната площадка
A6: 1 | B6: Анализ 1 | C6: Рязане на асфалтова настилка | D6: лин.м. | E6: 1457.75 | F6: ='Ед. Цени'!E4 -> 1.51 | G6: =ROUND(E6*F6,2) -> 2201.2 | J6: 1457.75
A7: 2 | B7: Анализ 2 | C7: Разваляне на съществуваща асфалтова настилка | D7: м3 | E7: 63.68 | F7: ='Ед. Цени'!E5 -> 1.65 | G7: =ROUND(E7*F7,2) -> 105.07 | J7: 63.68
A8: 3 | B8: Анализ 3 | C8: Разваляне на трошенокаменна настилка | D8: м3 | E8: 398.02 | F8: ='Ед. Цени'!E6 -> 1.38 | G8: =ROUND(E8*F8,2) -> 549.27 | J8: 398.02
A9: 4 | C9: Изкоп общо: | E9: 769.81 | J9: 769.81
A10: 5 | B10: Анализ 5 | C10: Механизиран изкоп- 75% - земна почва | D10: м3 | E10: 577.35 | F10: ='Ед. Цени'!E8 -> 6.5 | G10: =ROUND(E10*F10,2) -> 3752.78 | J10: 577.35
A11: 6 | B11: Анализ 6 | C11: Ръчен изкоп- 15%- земна почва | D11: м3 | E11: 115.47 | F11: ='Ед. Цени'!E9 -> 12.28 | G11: =ROUND(E11*F11,2) -> 1417.97 | J11: 115.47
A12: 7 | B12: Анализ 7 | C12: Изкоп с къртач- 10%- скална почва | D12: м3 | E12: 76.99 | F12: ='Ед. Цени'!E10 -> 20.68 | G12: =ROUND(E12*F12,2) -> 1592.15 | J12: 76.99
A13: 8 | B13: Анализ 8 | C13: Прехвърляне до 3м хор. или 2м верт. Разстояние ръчно, земни почви | D13: м3 | E13: 115.47 | F13: ='Ед. Цени'!E11 -> 4 | G13: =ROUND(E13*F13,2) -> 461.88 | J13: 115.47
A14: 9 | B14: Анализ 9 | C14: Неплътно укрепване и разкрепване на изкоп | D14: m² | E14: 1043.25 | F14: ='Ед. Цени'!E12 -> 1.86 | G14: =ROUND(E14*F14,2) -> 1940.45 | J14: 1043.25
A15: 10 | B15: Анализ 10 | C15: Направа на подложно легло от пясък- 10см | D15: м3 | E15: 70.5 | F15: ='Ед. Цени'!E13 -> 31.11 | G15: =ROUND(E15*F15,2) -> 2193.26 | J15: 70.5
A16: 11 | B16: Анализ 11 | C16: Доставка и полагане на полиетиленова сигнална лента | D16: лин.м. | E16: 850.75 | F16: ='Ед. Цени'!E14 -> 0.56 | G16: =ROUND(E16*F16,2) -> 476.42 | J16: 850.75
A17: 2. МОНТАЖНА ЧАСТ Ф 125
A18: 12 | B18: Анализ 72 | C18: Доставка и монтаж на полиетиленови тръби с висока плътност /ПЕВП/ ø125 PN 10, в изкоп | D18: лин.м. | E18: 607 | F18: ='Ед. Цени'!E75 -> 39.41 | G18: =ROUND(E18*F18,2) -> 23921.87 | J18: 607
A19: 13 | B19: Анализ 73 | C19: Заварки към ПЕВП тръби Ф125 | D19: бр. | E19: 102 | F19: ='Ед. Цени'!E76 -> 6.63 | G19: =ROUND(E19*F19,2) -> 676.26 | J19: 102
A20: 14 | B20: Анализ 74 | C20: Доставка и монтаж на HDPE тройник PN16 ∅125-90 | D20: бр. | E20: 17 | F20: ='Ед. Цени'!E77 -> 70.73 | G20: =ROUND(E20*F20,2) -> 1202.41 | J20: 17
A21: 15 | B21: Анализ 75 | C21: Доставка и монтаж на HDPE тапа PN16 ∅125 | D21: бр. | E21: 1 | F21: ='Ед. Цени'!E78 -> 36.22 | G21: =ROUND(E21*F21,2) -> 36.22 | J21: 1
A22: 16 | B22: Анализ 76 | C22: Заварки към ПЕВП 125 | D22: бр | E22: 4 | F22: ='Ед. Цени'!E79 -> 6.63 | G22: =ROUND(E22*F22,2) -> 26.52 | J22: 4
A23: 17 | B23: Анализ 20 | C23: опорен блок | D23: бр. | E23: 27 | F23: ='Ед. Цени'!E23 -> 20 | G23: =ROUND(E23*F23,2) -> 540 | J23: 27
A24: 3. МОНТАЖНА ЧАСТ СВО -39 броя
A25: 18 | B25: Анализ 77 | C25: Доставка и монтаж на полиетиленови тръби /ПЕВП / ø63, PN 10, в изкоп -за СВО | D25: m | E25: 25 | F25: ='Ед. Цени'!E80 -> 5.95 | G25: =ROUND(E25*F25,2) -> 148.75 | J25: 25
A26: 19 | B26: Анализ 50 | C26: Доставка и монтаж на полиетиленови тръби /ПЕВП / ø25, PN 10, в изкоп -за СВО | D26: m | E26: 218.75 | F26: ='Ед. Цени'!E53 -> 4.02 | G26: =ROUND(E26*F26,2) -> 879.38 | J26: 218.75
A27: 20 | B27: Анализ 78 | C27: Доставка и монтаж на тротоарен спирателен кран 2" с охранителна гарнитура, за СВО | D27: бр. | E27: 4 | F27: ='Ед. Цени'!E81 -> 130.61 | G27: =ROUND(E27*F27,2) -> 522.44 | J27: 4
A28: 21 | B28: Анализ 51 | C28: Доставка и монтаж на тротоарен спирателен кран 3/4" с охранителна гарнитура, за СВО | D28: бр. | E28: 35 | F28: ='Ед. Цени'!E54 -> 122.14 | G28: =ROUND(E28*F28,2) -> 4274.9 | J28: 35
A29: 22 | B29: Анализ 79 | C29: Доставка и монтаж на водовземна скоба,на резба, в/у тръби ПЕВП ∅125-2" | D29: бр. | E29: 35 | F29: ='Ед. Цени'!E82 -> 73.22 | G29: =ROUND(E29*F29,2) -> 2562.7 | J29: 35
A30: 23 | B30: Анализ 80 | C30: Доставка и монтаж на водовземна скоба,на резба, в/у тръби ПЕВП ∅200-3/4" | D30: бр. | E30: 4 | F30: ='Ед. Цени'!E83 -> 90.4 | G30: =ROUND(E30*F30,2) -> 361.6 | J30: 4
A31: 24 | B31: Анализ 53 | C31: Доставка и монтаж на тапа Ф25 | D31: бр. | E31: 39 | F31: ='Ед. Цени'!E56 -> 6.85 | G31: =ROUND(E31*F31,2) -> 267.15 | J31: 39
A32: 25 | B32: Анализ 54 | C32: Заварки към ПЕВП Ф25 | D32: бр | E32: 156 | F32: ='Ед. Цени'!E57 -> 2.48 | G32: =ROUND(E32*F32,2) -> 386.88 | J32: 156
A33: 4. Обратно засипване и възстановяване на настилки
A34: 26 | B34: Анализ 55 | C34: Обратен насип от пясък | D34: м3 | E34: 630.87 | F34: ='Ед. Цени'!E58 -> 31.11 | G34: =ROUND(E34*F34,2) -> 19626.37 | J34: 630.87
A35: 27 | B35: Анализ 56 | C35: Уплътняване с пневм. трамбовка през 20 см. | D35: м3 | E35: 630.87 | F35: ='Ед. Цени'!E59 -> 4 | G35: =ROUND(E35*F35,2) -> 2523.48 | J35: 630.87
A36: 28 | B36: Анализ 57 | C36: Възтановяване на основа от едро трошени камъни 35cm | D36: м3 | E36: 246.74 | F36: ='Ед. Цени'!E60 -> 31.11 | G36: =ROUND(E36*F36,2) -> 7676.08 | J36: 246.74
A37: 29 | B37: Анализ 58 | C37: Възтановяване на трошенокаменна настилка.15cm | D37: м3 | E37: 105.75 | F37: ='Ед. Цени'!E61 -> 31.11 | G37: =ROUND(E37*F37,2) -> 3289.88 | J37: 105.75
A38: 30 | B38: Анализ 59 | C38: Доставка и полагане на неплътен асфалтобетон за изравнителен пласт с дебелина в уплътнено състояние 4см | D38: тон | E38: 76.42 | F38: ='Ед. Цени'!E62 -> 125.82 | G38: =ROUND(E38*F38,2) -> 9615.16 | J38: 76.42
A39: 31 | B39: Анализ 60 | C39: Доставка и полагане на плътен асфалтобетон за износващ пласт с дебелина в уплътнено състояние 4см | D39: тон | E39: 76.42 | F39: ='Ед. Цени'!E63 -> 129.45 | G39: =ROUND(E39*F39,2) -> 9892.57 | J39: 76.42
A40: 32 | B40: Анализ 61 | C40: Натоварване на земни маси и извозването им до временно депо | D40: м3 | E40: 1167.83 | F40: ='Ед. Цени'!E64 -> 3.78 | G40: =ROUND(E40*F40,2) -> 4414.4 | J40: 1167.83
A41: 33 | B41: Анализ 62 | C41: Разриване на земни маси на депо | D41: м3 | E41: 1167.83 | F41: ='Ед. Цени'!E65 -> 2.48 | G41: =ROUND(E41*F41,2) -> 2896.22 | J41: 1167.83
...

Sheet Ф 90
A3: Обект: Реконструкция водопровод ул. Камчия с. Близнация о.т. 15-14а-12-36-34-41-42-38-37-61-64-84-82-80-90
A5: N | C5: НАИМЕНОВАНИЕ НА РАБОТИТЕ | D5: мярка | E5: КОЛИЧ. | F5: Ед.цена | G5: Обща ст-ст | I5: КОЛИЧ.
A6: Водопровод Ф90
A7: 1. Подготовка на строителната площадка
A8: 1 | B8: Анализ 1 | C8: Рязане на асфалтова настилка | D8: лин.м. | E8: 322 | F8: ='Ед. Цени'!E4 -> 1.51 | G8: =ROUND(E8*F8,2) -> 486.22 | I8: 322 | K8: =E8-I8 -> 0
A9: 2 | B9: Анализ 2 | C9: Разваляне на съществуваща асфалтова настилка | D9: м3 | E9: 11.59 | F9: ='Ед. Цени'!E5 -> 1.65 | G9: =ROUND(E9*F9,2) -> 19.12 | I9: 11.59 | K9: =E9-I9 -> 0
A10: 3 | B10: Анализ 3 | C10: Разваляне на трошенокаменна настилка | D10: м3 | E10: 72.45 | F10: ='Ед. Цени'!E6 -> 1.38 | G10: =ROUND(E10*F10,2) -> 99.98 | I10: 72.45 | K10: =E10-I10 -> 0
A11: 4 | C11: Изкоп общо: | E11: 104.33 | I11: 104.33 | K11: =E11-I11 -> 0
A12: 5 | B12: Анализ 5 | C12: Механизиран изкоп- 75% - земна почва | D12: м3 | E12: 78.25 | F12: ='Ед. Цени'!E8 -> 6.5 | G12: =ROUND(E12*F12,2) -> 508.63 | I12: 78.25 | K12: =E12-I12 -> 0
A13: 6 | B13: Анализ 6 | C13: Ръчен изкоп- 15%- земна почва | D13: м3 | E13: 15.65 | F13: ='Ед. Цени'!E9 -> 12.28 | G13: =ROUND(E13*F13,2) -> 192.18 | I13: 15.65 | K13: =E13-I13 -> 0
A14: 7 | B14: Анализ 7 | C14: Изкоп с къртач- 10%- скална почва | D14: м3 | E14: 10.43 | F14: ='Ед. Цени'!E10 -> 20.68 | G14: =ROUND(E14*F14,2) -> 215.69 | I14: 10.43 | K14: =E14-I14 -> 0
A15: 8 | B15: Анализ 8 | C15: Прехвърляне до 3м хор. или 2м верт. Разстояние ръчно, земни почви | D15: м3 | E15: 122.15 | F15: ='Ед. Цени'!E11 -> 4 | G15: =ROUND(E15*F15,2) -> 488.6 | I15: 122.15 | K15: =E15-I15 -> 0
A16: 9 | B16: Анализ 10 | C16: Направа на подложно легло от пясък- 10см | D16: м3 | E16: 16.97 | F16: ='Ед. Цени'!E13 -> 31.11 | G16: =ROUND(E16*F16,2) -> 527.94 | I16: 16.97 | K16: =E16-I16 -> 0
A17: 10 | B17: Анализ 11 | C17: Доставка и полагане на полиетиленова сигнална лента | D17: лин.м. | E17: 188.5 | F17: ='Ед. Цени'!E14 -> 0.56 | G17: =ROUND(E17*F17,2) -> 105.56 | I17: 188.5 | K17: =E17-I17 -> 0
A18: 2. МОНТАЖНА ЧАСТ | K18: =E18-I18 -> 0
A19: 11 | B19: Анализ 81 | C19: Доставка и монтаж на полиетиленови тръби с висока плътност /ПЕВП/ ø90, PN 10, в изкоп | D19: лин.м. | E19: 161 | F19: ='Ед. Цени'!E84 -> 17.95 | G19: =ROUND(E19*F19,2) -> 2889.95 | I19: 161 | K19: =E19-I19 -> 0
A20: 12 | B20: Анализ 82 | C20: Заварки към ПЕВП тръби Ф90 | D20: бр. | E20: 27 | F20: ='Ед. Цени'!E85 -> 4.09 | G20: =ROUND(E20*F20,2) -> 110.43 | I20: 27 | K20: =E20-I20 -> 0
A21: 13 | B21: Анализ 83 | C21: Доставка и монтаж на шибър PN10 Dn80 с охранителна гарнитура | D21: бр. | E21: 8 | F21: ='Ед. Цени'!E86 -> 150.22 | G21: =ROUND(E21*F21,2) -> 1201.76 | I21: 8 | K21: =E21-I21 -> 0
A22: 14 | B22: Анализ 84 | C22: Доставка и монтаж на шибър PN16 Dn80 с охранителна гарнитура | D22: бр. | E22: 17 | F22: ='Ед. Цени'!E87 -> 157.48 | G22: =ROUND(E22*F22,2) -> 2677.16 | I22: 17 | K22: =E22-I22 -> 0
A23: 15 | B23: Анализ 85 | C23: Доставка и монтаж на полиет. фланшов накрайник ø90 | D23: бр. | E23: 50 | F23: ='Ед. Цени'!E88 -> 34.97 | G23: =ROUND(E23*F23,2) -> 1748.5 | I23: 50 | K23: =E23-I23 -> 0
A24: 16 | B24: Анализ 86 | C24: Доставка и монтаж на свободен фланец OD90/Dn80 PN10 | D24: бр. | E24: 16 | F24: ='Ед. Цени'!E89 -> 33.87 | G24: =ROUND(E24*F24,2) -> 541.92 | I24: 16 | K24: =E24-I24 -> 0
A25: 17 | B25: Анализ 87 | C25: Доставка и монтаж на свободен фланец OD90/Dn80 PN16 | D25: бр. | E25: 34 | F25: ='Ед. Цени'!E90 -> 35.93 | G25: =ROUND(E25*F25,2) -> 1221.62 | I25: 34 | K25: =E25-I25 -> 0
A26: 18 | B26: Анализ 38 | C26: Доставка и монтаж на универсалeн адаптор ∅90 | D26: бр. | E26: 6 | F26: ='Ед. Цени'!E41 -> 73.91 | G26: =ROUND(E26*F26,2) -> 443.46 | I26: 6 | K26: =E26-I26 -> 0
A27: 19 | B27: Анализ 88 | C27: Заварки към ПЕВП 90 | D27: бр | E27: 72 | F27: ='Ед. Цени'!E91 -> 4.09 | G27: =ROUND(E27*F27,2) -> 294.48 | I27: 72 | K27: =E27-I27 -> 0
A28: 20 | B28: Анализ 20 | C28: опорен блок | D28: бр. | E28: 16 | F28: ='Ед. Цени'!E23 -> 20 | G28: =ROUND(E28*F28,2) -> 320 | I28: 16 | K28: =E28-I28 -> 0
A29: 3. Доставка и монтаж на ПХ- 7 броя | K29: =E29-I29 -> 0
A30: 21 | B30: Анализ 89 | C30: Доставка и монтаж на надземен пожарен хидрант ПХ80 | D30: бр. | E30: 10 | F30: ='Ед. Цени'!E92 -> 330.07 | G30: =ROUND(E30*F30,2) -> 3300.7 | I30: 10 | K30: =E30-I30 -> 0
A31: 22 | B31: Анализ 90 | C31: Тройник Ф110 ПЕВП | D31: бр | E31: 10 | F31: ='Ед. Цени'!E93 -> 60.08 | G31: =ROUND(E31*F31,2) -> 600.8 | I31: 10 | K31: =E31-I31 -> 0
A32: 23 | B32: Анализ 91 | C32: Коляно ПЕВП Ф90 90 ̊ | D32: бр | E32: 20 | F32: ='Ед. Цени'!E94 -> 40.79 | G32: =ROUND(E32*F32,2) -> 815.8 | I32: 20 | K32: =E32-I32 -> 0
A33: 24 | B33: Анализ 92 | C33: СФ Ф90 ̊ | D33: бр | E33: 20 | F33: ='Ед. Цени'!E95 -> 33.87 | G33: =ROUND(E33*F33,2) -> 677.4 | I33: 20 | K33: =E33-I33 -> 0
A34: 25 | B34: Анализ 93 | C34: ФН Ф90 ̊ | D34: бр | E34: 20 | F34: ='Ед. Цени'!E96 -> 34.97 | G34: =ROUND(E34*F34,2) -> 699.4 | I34: 20 | K34: =E34-I34 -> 0
A35: 26 | B35: Анализ 94 | C35: СК DN90 | D35: бр | E35: 20 | F35: ='Ед. Цени'!E97 -> 150.22 | G35: =ROUND(E35*F35,2) -> 3004.4 | I35: 20 | K35: =E35-I35 -> 0
A36: 27 | B36: Анализ 20 | C36: Опорен блок | D36: бр | E36: 20 | F36: ='Ед. Цени'!E23 -> 20 | G36: =ROUND(E36*F36,2) -> 400 | I36: 20 | K36: =E36-I36 -> 0
A37: 28 | B37: Анализ 88 | C37: Заварки към ПЕВП 90 | D37: бр | E37: 90 | F37: ='Ед. Цени'!E91 -> 4.09 | G37: =ROUND(E37*F37,2) -> 368.1 | I37: 90 | K37: =E37-I37 -> 0
A38: 29 | B38: Анализ 95 | C38: Доставка и монтаж на табели за обозначаване на ПХ и СК | D38: бр. | E38: 10 | F38: ='Ед. Цени'!E98 -> 12.3 | G38: =ROUND(E38*F38,2) -> 123 | I38: 10 | K38: =E38-I38 -> 0
A39: 3. Обратно засипване и възстановяване на настилки | K39: =E39-I39 -> 0
A40: 30 | B40: Анализ 55 | C40: Обратен насип от пясък | D40: м3 | E40: 95.3 | F40: ='Ед. Цени'!E58 -> 31.11 | G40: =ROUND(E40*F40,2) -> 2964.78 | I40: 95.3 | K40: =E40-I40 -> 0
A41: 31 | B41: Анализ 56 | C41: Уплътняване с пневм. трамбовка през 20 см. | D41: м3 | E41: 95.3 | F41: ='Ед. Цени'!E59 -> 4 | G41: =ROUND(E41*F41,2) -> 381.2 | I41: 95.3 | K41: =E41-I41 -> 0
A42: 32 | B42: Анализ 57 | C42: Възтановяване на основа от едро трошени камъни 35cm | D42: м3 | E42: 59.38 | F42: ='Ед. Цени'!E60 -> 31.11 | G42: =ROUND(E42*F42,2) -> 1847.31 | I42: 59.38 | K42: =E42-I42 -> 0
A43: 33 | B43: Анализ 58 | C43: Възтановяване на трошенокаменна настилка.15cm | D43: м3 | E43: 25.45 | F43: ='Ед. Цени'!E61 -> 31.11 | G43: =ROUND(E43*F43,2) -> 791.75 | I43: 25.45 | K43: =E43-I43 -> 0
...

Sheet Рекапитулация
A1: Обособена позиция № 2: „Реконструкция на водопровод ул. Камчия с. Близнаци о.т.15-14а-12-36-34-41-42-38-37-61-64-84-82-80-93 общ. Аврен, обл. Варна“
A4: Номер | B4: Наименование | C4: Обща ст-ст | D4: Пределна цена в ЕВРО | E4: метри | F4: за м'
A5: 1 | B5: Реконструкция водопровод ул. Камчия с. Близнация о.т. 15-14а-12-36-34-41-42-38-37-61-64-84-82-80-90- Ф 200 | C5: =Ф200!G79 -> 125964.65 | D5: 135293.78 | E5: =Ф200!E18 -> 464 | F5: =C5/E5 -> 271.47554 | H5: =D5-C5 -> 9329.13
A6: 2 | B6: Реконструкция водопровод ул. Камчия с. Близнация о.т. 15-14а-12-36-34-41-42-38-37-61-64-84-82-80-90- Ф 160 | C6: =Ф160!G40 -> 103933.75 | D6: 113763.7 | E6: 607 | F6: =C6/E6 -> 171.22529 | H6: =D6-C6 -> 9829.95
A7: 3 | B7: Реконструкция водопровод ул. Камчия с. Близнация о.т. 15-14а-12-36-34-41-42-38-37-61-64-84-82-80-90- Ф 125 | C7: ='Ф 125'!G46 -> 119093.79 | D7: 128424.74 | E7: 607 | F7: =C7/E7 -> 196.20064 | H7: =D7-C7 -> 9330.95
A8: 4 | B8: Реконструкция водопровод ул. Камчия с. Близнация о.т. 15-14а-12-36-34-41-42-38-37-61-64-84-82-80-90- Ф 90 | C8: ='Ф 90'!G52 -> 38850.9 | D8: 38994.99 | E8: 161 | F8: =C8/E8 -> 241.30994 | H8: =D8-C8 -> 144.09
B9: Всичко без ДДС: | C9: =SUM(C5:C8) -> 387843.09 | D9: 416477.21 | E9: =D9-C9 -> 28634.12 | F9: =D9/E9 -> 14.544788 | G9: евро
B10: ДДС 20 %: | C10: =0.2*C9 -> 77568.618 | H10: =E9*1.98553 -> 56853.904
B11: Всичко с ДДС: | C11: =C9+C10 -> 465411.71

Sheet Ед. Цени
A1: КСС - Обособена позиция № 2: „Реконструкция на водопровод ул. Камчия с. Близнаци о.т.15-14а-12-36-34-41-42-38-37-61-64-84-82-80-93 общ. Аврен, обл. Варна“
C2: ЕД. ЦЕНИ ОП 2
A3: N | C3: НАИМЕНОВАНИЕ НА РАБОТИТЕ | D3: мярка | E3: Ед.цена (EU)
A4: 1 | B4: Анализ 1 | C4: Рязане на асфалтова настилка | D4: лин.м. | E4: 1.51
A5: 2 | B5: Анализ 2 | C5: Разваляне на съществуваща асфалтова настилка | D5: м3 | E5: 1.65
A6: 3 | B6: Анализ 3 | C6: Разваляне на трошенокаменна настилка | D6: м3 | E6: 1.38
A7: 4 | C7: Изкоп общо: | E7: 0
A8: 5 | B8: Анализ 5 | C8: Механизиран изкоп- 75% - земна почва | D8: м3 | E8: 6.5
A9: 6 | B9: Анализ 6 | C9: Ръчен изкоп- 15% - земна почва | D9: м3 | E9: 12.28
A10: 7 | B10: Анализ 7 | C10: Изкоп с къртач- 10% - скална почва | D10: м3 | E10: 20.68
A11: 8 | B11: Анализ 8 | C11: Прехвърляне до 3м хор. или 2м верт. Разстояние ръчно, земни почви | D11: м3 | E11: 4
A12: 9 | B12: Анализ 9 | C12: Неплътно укрепване и разкрепване на изкоп | D12: m² | E12: 1.86
A13: 10 | B13: Анализ 10 | C13: Направа на подложно легло от пясък- 10см | D13: м3 | E13: 31.11
A14: 11 | B14: Анализ 11 | C14: Доставка и полагане на полиетиленова сигнална лента | D14: лин.м. | E14: 0.56
A15: 12 | B15: Анализ 12 | C15: Доставка и монтаж на полиетиленови тръби с висока плътност /ПЕВП/ ø200, PN 10, в изкоп | D15: лин.м. | E15: 40.87
A16: 13 | B16: Анализ 13 | C16: Заварки към ПЕВП тръби Ф200 | D16: бр. | E16: 7.85
A17: 14 | B17: Анализ 14 | C17: Доставка и монтаж на шибър PN10 Dn200 с охранителна гарнитура | D17: бр. | E17: 270.01
A18: 15 | B18: Анализ 15 | C18: Доставка и монтаж на полиет. фланшов накрайник ø200 | D18: бр. | E18: 65.27
A19: 16 | B19: Анализ 16 | C19: Доставка и монтаж на свободен фланец OD200/Dn200 PN10 | D19: бр. | E19: 59.52
... A98: 29 | B98: Анализ 95 | C98: Доставка и монтаж на табели за обозначаване на ПХ и СК | D98: бр. | E98: 12.3

Sheet Анализи
B1: ОП 2 Близнаци
A2: АНАЛИЗНИ ЦЕНИ (МАТ., МЕХ., ДРУГИ И ТРУД)
A4: Осн. | B4: Описание | C4: м-ка | D4: РН | E4: К | F4: Цена | G4: Общо
A5: [1] | B5: [2] | C5: [3] | D5: [4] | E5: [5] | F5: [6] | G5: [7]
A8: Рязане на асфалтова настилка
A9: Позиция: , Основание: Анализ 1 | G9: за лин.м.
B11: Механизация | G11: 0.81
A12: - | B12: ФУГОРЕЗ - РЪЧЕН | C12: МСМ | D12: 0.027 | E12: 1 | F12: 30 | G12: 0.81
B14: Труд | D14: 0.02 | G14: 0.2
A15: - | B15: РАБОТНИК 02 | C15: Ч.Ч. | D15: 0.02 | E15: 1 | F15: 10 | G15: 0.2
B17: Допълнителни разходи | G17: 0.36
B18: върху Труд | C18: % | D18: 80 | G18: 0.16
B19: върху Механизация | C19: % | D19: 25 | G19: 0.2
B21: Общо
B22: преки | G22: 1.01
B23: допълнителни | G23: 0.36
B24: общо | G24: 1.37
B25: печалба | C25: % | D25: 10 | G25: 0.14
B27: Общо | G27: 1.51
A29: Разваляне на съществуваща асфалтова настилка
A30: Позиция: , Основание: Анализ 2 | G30: за м3
B32: Механизация | G32: 1.2
A33: - | B33: Багер многокофов, с хидрочук | C33: МСМ | D33: 0.0048 | E33: 1 | F33: 250 | G33: 1.2
B35: Допълнителни разходи | G35: 0.3
B36: върху Механизация | C36: % | D36: 25 | G36: 0.3
B38: Общо
B39: преки | G39: 1.2
B40: допълнителни | G40: 0.3
B41: общо | G41: 1.5
B42: печалба | C42: % | D42: 10 | G42: 0.15
B44: Общо | G44: 1.65
A46: Разваляне на трошенокаменна настилка
A47: Позиция: , Основание: Анализ 3 | G47: за м3
B49: Механизация | G49: 1
A50: - | B50: Багер многокофов | C50: МСМ | D50: 0.004 | E50: 1 | F50: 250 | G50: 1
B52: Допълнителни разходи | G52: 0.25
B53: върху Механизация | C53: % | D53: 25 | G53: 0.25
B55: Общо
B56: преки | G56: 1
B57: допълнителни | G57: 0.25
...
