Workbook
Name _Hlk165973344: КСС_ОП1!$A$7

Sheet КСС_ОП1
G1: Приложение 2.1
A2: ВЪЗЛОЖИТЕЛ: ОБЩИНА ШАБЛА
A3: ОБЕКТ: „Реконструкция и рехабилитация на водоснабдителни системи и съоръжения в община Шабла по 3 (три) обособени позиции: Обособена позиция №1: „Реконструкция и рехабилитация на водоснабдителни системи и съоръжения в с. Горун, община Шабла“
A6: КОЛИЧЕСТВЕНО - СТОЙНОСТНА СМЕТКА (КСС)
A7: № по ред | C7: Наименование на работите | D7: Ед. мярка | E7: Колич. | F7: Ед. цена | G7: Стойност
A8: Водопроводен клон 3 - по ул. "3-та"от ОТ17 до ОТ39 и до края на улицата след ОТ36 - L=418 m'
A9: I. | C9: Строителна част
A10: 1 | C10: Направа на изкоп по детайл на транспорт за основен водопровод(0,80x1,70m') и СВО(0,50x1,20m')
B11: Анализ 1 | C11: - машинен в земни почви 100 % | D11: m3 | E11: 605 | F11: ='Ед. Цени'!E11 -> 5.57 | G11: =ROUND(E11*F11,2) -> 3369.85
A12: 2 | B12: Анализ 2 | C12: Извозване на излишни земни маси от масов изкоп за водопровод и СВО за оползотворяване или депониране (до 5 км) | D12: m3 | E12: 181 | F12: ='Ед. Цени'!E12 -> 2.79 | G12: =ROUND(E12*F12,2) -> 504.99
A13: 3 | B13: Анализ 3 | C13: Неплътно укрепване и разкрепване за основен водопровод - 1,8 m2/m' | D13: m2 | E13: 752 | F13: ='Ед. Цени'!E13 -> 1.38 | G13: =ROUND(E13*F13,2) -> 1037.76
A14: 4 | B14: Анализ 4 | C14: Направа на подложка, странична засипка и пласт насип над тръби (20см) за основен водопровод и СВО в макадамови и непланирани улици и тротоари от дребнозърнест скален материал (трошен пясък) фракция 0-4 мм, вкл. доставка от 100 km, складиране и уплътняване | D14: m3 | E14: 140 | F14: ='Ед. Цени'!E14 -> 36.6 | G14: =ROUND(E14*F14,2) -> 5124
A15: 5 | B15: Анализ 5 | C15: Обратна засипка на основна траншея и СВО със земна маса (0-30 mm) и уплътняване с вибро трамбовка през 30см | D15: m3 | E15: 424 | F15: ='Ед. Цени'!E15 -> 8.88 | G15: =ROUND(E15*F15,2) -> 3765.12
A16: 6 | B16: Анализ 6 | C16: Водочерпене по време на строителството | D16: мсм | E16: 8 | F16: ='Ед. Цени'!E16 -> 17.33 | G16: =ROUND(E16*F16,2) -> 138.64
A17: 7 | B17: Анализ 7 | C17: Доставка и полагане на пътна основа в макадамови улици от трошен камък с непрекъсната зърнометрия, вкл.превоз и уплътняване (фракция 0-63) Е=250 Mpa (до 80km) | D17: m3 | E17: 41 | F17: ='Ед. Цени'!E17 -> 33.08 | G17: =ROUND(E17*F17,2) -> 1356.28
A18: II. | C18: Монтажна част
A19: 1 | B19: Анализ 8 | C19: Доставка, полагане и монтаж на тръби ∅90 PE100 PN10 | D19: m' | E19: 299 | F19: ='Ед. Цени'!E18 -> 18.44 | G19: =ROUND(E19*F19,2) -> 5513.56
A20: 2 | B20: Анализ 9 | C20: Доставка, полагане и монтаж на тръби ∅63 PE100 PN10 | D20: m' | E20: 119 | F20: ='Ед. Цени'!E19 -> 7.05 | G20: =ROUND(E20*F20,2) -> 838.95
A21: 3 | B21: Анализ 10 | C21: Доставка и монтаж на предфланшова връзка ∅90 PE100 PN10 | D21: бр. | E21: 2 | F21: ='Ед. Цени'!E20 -> 36.21 | G21: =ROUND(E21*F21,2) -> 72.42
A22: 4 | B22: Анализ 11 | C22: Доставка и монтаж на предфланшова връзка ∅63 PE100 PN10 | D22: бр. | E22: 1 | F22: ='Ед. Цени'!E21 -> 26.26 | G22: =ROUND(E22*F22,2) -> 26.26
A23: 5 | B23: Анализ 12 | C23: Доставка и монтаж на тройник ∅90-90-90 PE100 PN10 | D23: бр. | E23: 3 | F23: ='Ед. Цени'!E22 -> 48.31 | G23: =ROUND(E23*F23,2) -> 144.93
A24: 6 | B24: Анализ 13 | C24: Доставка и монтаж на тройник намалител ∅90-63-90 PE100 PN10 | D24: бр. | E24: 2 | F24: ='Ед. Цени'!E23 -> 50.73 | G24: =ROUND(E24*F24,2) -> 101.46
A25: 7 | B25: Анализ 14 | C25: Доставка и монтаж на намалител ∅90-63 PE100 PN10 | D25: бр. | E25: 1 | F25: ='Ед. Цени'!E24 -> 26.86 | G25: =ROUND(E25*F25,2) -> 26.86
A26: 8 | B26: Анализ 15 | C26: Доставка и монтаж на коляно 90гр. ∅90 РЕ100 PN10 | D26: бр. | E26: 1 | F26: ='Ед. Цени'!E25 -> 32.58 | G26: =ROUND(E26*F26,2) -> 32.58
A27: 9 | B27: Анализ 16 | C27: Доставка и монтаж на коляно 90гр. ∅63 РЕ100 PN10 | D27: бр. | E27: 1 | F27: ='Ед. Цени'!E26 -> 27.47 | G27: =ROUND(E27*F27,2) -> 27.47
A28: 10 | B28: Анализ 17 | C28: Доставка и монтаж на тапа ∅63РЕ100 PN10 | D28: бр. | E28: 1 | F28: ='Ед. Цени'!E27 -> 23.84 | G28: =ROUND(E28*F28,2) -> 23.84
A29: 11 | B29: Анализ 18 | C29: Доставка и монтаж на СК DN50 шибърен ,чугун, с гумиран клин, с охранителна гарнитура | D29: бр. | E29: 1 | F29: ='Ед. Цени'!E28 -> 138.6 | G29: =ROUND(E29*F29,2) -> 138.6
A30: 12 | B30: Анализ 19 | C30: Доставка и монтаж на СК DN80 шибърен ,чугун, с гумиран клин, с охранителна гарнитура | D30: бр. | E30: 2 | F30: ='Ед. Цени'!E29 -> 150.7 | G30: =ROUND(E30*F30,2) -> 301.4
... A38: 20 | B38: Анализ 27 | C38: Доставка и монтаж на преход с електрозаваряема муфа PE-метал ∅63-2" с външна резба | D38: бр. | E38: 2 | F38: ='Ед. Цени'!E37 -> 32.45 | G38: =ROUND(E38*F38,2) -> 64.9
A39: 21 | C39: СВО ∅63-3/4" | D39: бр. | E39: 4
A40: - | B40: Анализ 28 | C40: Доставка и монтаж на тръби ∅25 PE100 PN10 за сградни водопроводни отклонения- 1 брой СВО | D40: m' | E40: =E39*6 -> 24 | F40: ='Ед. Цени'!E38 -> 5.29 | G40: =ROUND(E40*F40,2) -> 126.96
A41: - | B41: Анализ 29 | C41: Доставка и монтаж на водовземна скоба за РЕ електрозаваряема ∅63-3/4" | D41: бр. | E41: =E39*1 -> 4 | F41: ='Ед. Цени'!E39 -> 43.11 | G41: =ROUND(E41*F41,2) -> 172.44
A42: - | B42: Анализ 30 | C42: Доставка и монтаж на преход външна резба ∅25-3/4" вкл. електрозаваряема муфа ∅25 | D42: бр. | E42: =E39*2 -> 8 | F42: ='Ед. Цени'!E40 -> 24.34 | G42: =ROUND(E42*F42,2) -> 194.72
A43: - | B43: Анализ 31 | C43: Доставка и монтаж на ТСК ∅3/4" | D43: бр. | E43: =E39*1 -> 4 | F43: ='Ед. Цени'!E41 -> 128.92 | G43: =ROUND(E43*F43,2) -> 515.68
A44: - | B44: Анализ 32 | C44: Доставка и монтаж на преход с електрозаваряема муфа PE-метал ∅25-3/4" с вътрешна резба | D44: бр. | E44: =E39*1 -> 4 | F44: ='Ед. Цени'!E42 -> 25.8 | G44: =ROUND(E44*F44,2) -> 103.2
A45: 22 | C45: СВО ∅90-3/4" | D45: бр. | E45: 10
A46: - | B46: Анализ 28 | C46: Доставка и монтаж на тръби ∅25 PE100 PN10 за сградни водопроводни отклонения- 1 брой СВО | D46: m' | E46: =E45*6 -> 60 | F46: ='Ед. Цени'!E38 -> 5.29 | G46: =ROUND(E46*F46,2) -> 317.4
A47: - | B47: Анализ 33 | C47: Доставка и монтаж на водовземна скоба за РЕ електрозаваряема ∅90-3/4" вкл. муфа ∅25 | D47: бр. | E47: =E45*1 -> 10 | F47: ='Ед. Цени'!E43 -> 64.92 | G47: =ROUND(E47*F47,2) -> 649.2
A48: - | B48: Анализ 30 | C48: Доставка и монтаж на преход външна резба ∅25-3/4" вкл. електрозаваряема муфа ∅25 | D48: бр. | E48: =E45*2 -> 20 | F48: ='Ед. Цени'!E40 -> 24.34 | G48: =ROUND(E48*F48,2) -> 486.8
A49: - | B49: Анализ 31 | C49: Доставка и монтаж на ТСК ∅3/4" | D49: бр. | E49: =E45*1 -> 10 | F49: ='Ед. Цени'!E41 -> 128.92 | G49: =ROUND(E49*F49,2) -> 1289.2
...

Sheet Ед. Цени
A2: ВЪЗЛОЖИТЕЛ: ОБЩИНА ШАБЛА
A3: ОБЕКТ: „Реконструкция и рехабилитация на водоснабдителни системи и съоръжения в община Шабла по 3 (три) обособени позиции: Обособена позиция №1: „Реконструкция и рехабилитация на водоснабдителни системи и съоръжения в с. Горун, община Шабла“
A5: ЕДИНИЧНИ ЦЕНИ
A7: № по ред | C7: Наименование на работите | D7: Ед. мярка | E7: Ед. цена
A8: Водопроводен клон 3 - по ул. "3-та"от ОТ17 до ОТ39 и до края на улицата след ОТ36 - L=418 m'
A9: I. | C9: Строителна част
A10: 1 | B10: Анализ 1 | C10: Направа на изкоп по детайл на транспорт за основен водопровод(0,80x1,70m') и СВО(0,50x1,20m')
C11: - машинен в земни почви 100 % | D11: m3 | E11: 5.57 | F11: =E11-G11 -> 0 | G11: 5.57
A12: 2 | B12: Анализ 2 | C12: Извозване на излишни земни маси от масов изкоп за водопровод и СВО за оползотворяване или депониране (до 5 км) | D12: m3 | E12: 2.79 | F12: =E12-G12 -> 0 | G12: 2.79
A13: 3 | B13: Анализ 3 | C13: Неплътно укрепване и разкрепване за основен водопровод - 1,8 m2/m' | D13: m2 | E13: 1.38 | F13: =E13-G13 -> 0 | G13: 1.38
A14: 4 | B14: Анализ 4 | C14: Направа на подложка, странична засипка и пласт насип над тръби (20см) за основен водопровод и СВО в макадамови и непланирани улици и тротоари от дребнозърнест скален материал (трошен пясък) фракция 0-4 мм, вкл. доставка от 100 km, складиране и уплътняване | D14: m3 | E14: 36.6 | F14: =E14-G14 -> 0 | G14: 36.6
A15: 5 | B15: Анализ 5 | C15: Обратна засипка на основна траншея и СВО със земна маса (0-30 mm) и уплътняване с вибро трамбовка през 30см | D15: m3 | E15: 8.88 | F15: =E15-G15 -> 0 | G15: 8.88
A16: 6 | B16: Анализ 6 | C16: Водочерпене по време на строителството | D16: мсм | E16: 17.33 | F16: =E16-G16 -> 0 | G16: 17.33
A17: 7 | B17: Анализ 7 | C17: Доставка и полагане на пътна основа в макадамови улици от трошен камък с непрекъсната зърнометрия, вкл.превоз и уплътняване (фракция 0-63) Е=250 Mpa (до 80km) | D17: m3 | E17: 33.08 | F17: =E17-G17 -> 0 | G17: 33.08
A18: 1 | B18: Анализ 8 | C18: Доставка, полагане и монтаж на тръби ∅90 PE100 PN10 | D18: m' | E18: 18.44 | F18: =E18-G18 -> -7.61 | G18: 26.05
A19: 2 | B19: Анализ 9 | C19: Доставка, полагане и монтаж на тръби ∅63 PE100 PN10 | D19: m' | E19: 7.05 | F19: =E19-G19 -> 0 | G19: 7.05
A20: 3 | B20: Анализ 10 | C20: Доставка и монтаж на предфланшова връзка ∅90 PE100 PN10 | D20: бр. | E20: 36.21 | F20: =E20-G20 -> 0 | G20: 36.21
A21: 4 | B21: Анализ 11 | C21: Доставка и монтаж на предфланшова връзка ∅63 PE100 PN10 | D21: бр. | E21: 26.26 | F21: =E21-G21 -> 0 | G21: 26.26
A22: 5 | B22: Анализ 12 | C22: Доставка и монтаж на тройник ∅90-90-90 PE100 PN10 | D22: бр. | E22: 48.31 | F22: =E22-G22 -> 0 | G22: 48.31
A23: 6 | B23: Анализ 13 | C23: Доставка и монтаж на тройник намалител ∅90-63-90 PE100 PN10 | D23: бр. | E23: 50.73 | F23: =E23-G23 -> 0 | G23: 50.73
... A37: 20 | B37: Анализ 27 | C37: Доставка и монтаж на преход с електрозаваряема муфа PE-метал ∅63-2" с външна резба | D37: бр. | E37: 32.45 | F37: =E37-G37 -> 0 | G37: 32.45
A38: - | B38: Анализ 28 | C38: Доставка и монтаж на тръби ∅25 PE100 PN10 за сградни водопроводни отклонения- 1 брой СВО | D38: m' | E38: 5.29 | F38: =E38-G38 -> 0 | G38: 5.29
A39: - | B39: Анализ 29 | C39: Доставка и монтаж на водовземна скоба за РЕ електрозаваряема ∅63-3/4" | D39: бр. | E39: 43.11 | F39: =E39-G39 -> 0 | G39: 43.11
A40: - | B40: Анализ 30 | C40: Доставка и монтаж на преход външна резба ∅25-3/4" вкл. електрозаваряема муфа ∅25 | D40: бр. | E40: 24.34 | F40: =E40-G40 -> 0 | G40: 24.34
A41: - | B41: Анализ 31 | C41: Доставка и монтаж на ТСК ∅3/4" | D41: бр. | E41: 128.92 | F41: =E41-G41 -> 0 | G41: 128.92
A42: - | B42: Анализ 32 | C42: Доставка и монтаж на преход с електрозаваряема муфа PE-метал ∅25-3/4" с вътрешна резба | D42: бр. | E42: 25.8 | F42: =E42-G42 -> 0 | G42: 25.8
A43: - | B43: Анализ 33 | C43: Доставка и монтаж на водовземна скоба за РЕ електрозаваряема ∅90-3/4" вкл. муфа ∅25 | D43: бр. | E43: 64.92 | F43: =E43-G43 -> 0 | G43: 64.92
A44: 23 | B44: Анализ 34 | C44: Доставка и монтаж на детекторна сигнална лента с метална нишка | D44: m' | E44: 1.5 | F44: =E44-G44 -> 0 | G44: 1.5
A45: 24 | B45: Анализ 35 | C45: Доставка и монтаж на сигнална лента "Водопровод" | D45: m' | E45: 0.9 | F45: =E45-G45 -> 0 | G45: 0.9
A46: 25 | B46: Анализ 36 | C46: Изпитване на водопровода | D46: m' | E46: 2.23 | F46: =E46-G46 -> 0 | G46: 2.23
A47: 26 | B47: Анализ 37 | C47: Дезинфекция на водопровода | D47: m' | E47: 1.75 | F47: =E47-G47 -> 0 | G47: 1.75
A48: 27 | B48: Анализ 38 | C48: Доставка и монтаж на муфа електрозаваряема ∅63 (вкл.самата заварка) | D48: бр. | E48: 20.15 | F48: =E48-G48 -> 0 | G48: 20.15
A49: 28 | B49: Анализ 39 | C49: Доставка и монтаж на муфа електрозаваряема ∅90 (вкл.самата заварка) | D49: бр. | E49: 24.99 | F49: =E49-G49 -> 0 | G49: 24.99
A50: 4 | B50: Анализ 40 | C50: Направа на подложка, странична засипка и пласт насип над тръби (20см) за основен водопровод и СВО в непланирани улици и тротоари от дребнозърнест скален материал (трошен пясък) фракция 0-4 мм, вкл. доставка от 100 km, складиране и уплътняване | D50: m3 | E50: 36.6 | F50: =E50-G50 -> 0 | G50: 36.6
A51: 4 | B51: Анализ 41 | C51: Направа на подложка, странична засипка и пласт насип над тръби (20см) за основен водопровод и СВО в макадамови улици и тротоари от дребнозърнест скален материал (трошен пясък) фракция 0-4 мм, вкл. доставка от 100 km, складиране и уплътняване | D51: m3 | E51: 36.6 | F51: =E51-G51 -> 0 | G51: 36.6
A52: 1 | B52: Анализ 42 | C52: Рязане на асфалтова настилка | D52: m' | E52: 1.74 | F52: =E52-G52 -> 0 | G52: 1.74
A53: 2 | B53: Анализ 43 | C53: Разкъртване на асфалтова настилка за основен водопровод и СВО - механизирано (10см пласт) | D53: m2 | E53: 3.43 | F53: =E53-G53 -> 0 | G53: 3.43
A54: 3 | B54: Анализ 44 | C54: Натоварване и извозване на строителни отпадъци на постоянно депо (до 100 км) | D54: m3 | E54: 4.08 | F54: =E54-G54 -> 0 | G54: 4.08
A55: 7 | B55: Анализ 45 | C55: Направа на подложка, странична засипка и пласт насип над тръби (20см) за основен водопровод и СВО в асфалтови улици от дребнозърнест скален материал (трошен пясък) фракция 0-4 мм, вкл. доставка от 100 km, складиране и уплътняване | D55: m3 | E55: 36.6 | F55: =E55-G55 -> 0 | G55: 36.6
... A70: 5 | B70: Анализ 60 | C70: Доставка и монтаж на тройник намалител ∅90-63-90 PE100 PN10 | D70: бр. | E70: 50.73 | F70: =E70-G70 -> 0 | G70: 50.73
...

Sheet Анализи
