Workbook

Sheet кл.I.3
A1: Обект: Реконструкция на компрометирани участъци от водопроводната мрежа в с.Апарухово, Общ.Дългопол- етап 2
A2: Възложител: Община Дългопол
A4: KОЛИЧЕСТВЕНО- СТОЙНОСТНА СМЕТКА - клон I.3 /о.т. 100 до о.т.89/
C7: СВО-къси | D7: 11
C8: СВО-дълги | D8: 15
C9: ПХ | D9: 2
C10: Широчина изкоп | D10: 1.1
C11: Широчина разваляне и възстановяване наст. | D11: 1.4
C12: Дълбочина изкоп | D12: 1.71
C13: Широчина регулация | D13: 10
C14: Широчина асфалт | D14: 6
A16: № | C16: Вид СМР | D16: М-ка | E16: Количество | F16: Ед. цена | G16: Стойност
A19: 1 | C19: 2 | D19: 3 | E19: 4 | F19: 5 | G19: 6
A20: I. ЧАСТ ВОДОСНАБДЯВАНЕ
A21: 1 | B21: анализ 1 | C21: Рязане с фугорез на асфалтова настилка | D21: л.м. | E21: 1052.4 | F21: ='Ед. Цени'!F21 -> 3.53 | G21: =ROUND((E21*F21),2) -> 3714.97
A22: 2 | B22: анализ 2 | C22: Разваляне асфалтова настилка | D22: м2 | E22: 736.68 | F22: ='Ед. Цени'!F22 -> 6.89 | G22: =ROUND((E22*F22),2) -> 5075.73
A23: 3 | B23: анализ 3 | C23: Изкоп с багер на отвал ЗП неукрепен - спада се от т.4 | D23: м3 | E23: 694.16424 | F23: ='Ед. Цени'!F23 -> 5.5 | G23: =ROUND((E23*F23),2) -> 3817.9
A24: 4 | B24: анализ 4 | C24: Изкоп с дълб. до 2м. ръчно - 30% | D24: м3 | E24: 297.49896 | F24: ='Ед. Цени'!F24 -> 24.35 | G24: =ROUND((E24*F24),2) -> 7244.1
A25: 5 | B25: анализ 5 | C25: Прехвърляне на изкопана земна маса на 2,00 м вертикално и хоризонтално | D25: м3 | E25: 297.49896 | F25: ='Ед. Цени'!F25 -> 12.47 | G25: =ROUND((E25*F25),2) -> 3709.81
A26: 6 | B26: анализ 6 | C26: Натоварване излишната пръст с багер на самосвал | D26: м3 | E26: 991.6632 | F26: ='Ед. Цени'!F26 -> 2.79 | G26: =ROUND((E26*F26),2) -> 2766.74
A27: 7 | B27: анализ 7 | C27: Разриване с булдозер на земни маси | D27: м3 | E27: 991.6632 | F27: ='Ед. Цени'!F27 -> 1.98 | G27: =ROUND((E27*F27),2) -> 1963.49
A28: 8 | B28: анализ 8 | C28: Превоз на земни маси със самосвал до 5км. | D28: м3 | E28: 991.6632 | F28: ='Ед. Цени'!F28 -> 2.79 | G28: =ROUND((E28*F28),2) -> 2766.74
A29: 9 | B29: анализ 9 | C29: Неплътно укрепване и разкрепване на изкопи | D29: м2 | E29: 1799.604 | F29: ='Ед. Цени'!F29 -> 2.42 | G29: =ROUND((E29*F29),2) -> 4355.04
A30: 10 | B30: анализ 10 | C30: Доставка на пясък със самосвал на 10км. | D30: м3 | E30: 289.96 | F30: ='Ед. Цени'!F30 -> 19.04 | G30: =ROUND((E30*F30),2) -> 5520.84
A31: 11 | B31: анализ 11 | C31: Превоз с ръчни колички на пясък на 50м | D31: м3 | E31: 289.96 | F31: ='Ед. Цени'!F31 -> 6.14 | G31: =ROUND((E31*F31),2) -> 1780.35
A32: 12 | B32: анализ 12 | C32: Подложка от пясък 10см. | D32: м3 | E32: 57.992 | F32: ='Ед. Цени'!F32 -> 8.17 | G32: =ROUND((E32*F32),2) -> 473.79
... A69: 49 | B69: анализ 49 | C69: Доставка и монтажна детекторна лента над водопровода | D69: л.м. | E69: 527.2 | F69: ='Ед. Цени'!F69 -> 1.41 | G69: =ROUND((E69*F69),2) -> 743.35
C70: Общо за част Водоснабдяване: | G70: =SUM(G21:G69) -> 103304.56
A71: II. ЧАСТ ВЪЗСТАНОВЯВАНЕ НА НАСТИЛКАТА
A72: 1 | B72: анализ 50 | C72: Изкоп на земни почви с багер на транспорт | D72: м3 | E72: 76.33 | F72: ='Ед. Цени'!F70 -> 7.8 | G72: =ROUND((E72*F72),2) -> 595.37
A73: 2 | B73: анализ 51 | C73: Изкоп ръчен в земни почви | D73: м3 | E73: 32.71 | F73: ='Ед. Цени'!F71 -> 16.63 | G73: =ROUND((E73*F73),2) -> 543.97
A74: 3 | B74: анализ 52 | C74: Почистване на реголи и настилки от кал | D74: м2 | E74: 180.48 | F74: ='Ед. Цени'!F72 -> 6.09 | G74: =ROUND((E74*F74),2) -> 1099.12
A75: 4 | B75: анализ 53 | C75: Натоварване разк. земна почва на транспорт с багер | D75: м3 | E75: 39.25 | F75: ='Ед. Цени'!F73 -> 1.64 | G75: =ROUND((E75*F75),2) -> 64.37
A76: 5 | B76: анализ 54 | C76: Извозване на депо земни почви до 10 км | D76: м3 | E76: 112.8 | F76: ='Ед. Цени'!F74 -> 8.54 | G76: =ROUND((E76*F76),2) -> 963.31
A77: 6 | B77: анализ 7 | C77: Разриване с булдозер на земни маси | D77: м3 | E77: 112.8 | F77: ='Ед. Цени'!F27 -> 1.98 | G77: =ROUND((E77*F77),2) -> 223.34
A78: 7 | B78: анализ 55 | C78: Фрезоване на асфалт | D78: м2 | E78: 1880 | F78: ='Ед. Цени'!F75 -> 1.78 | G78: =ROUND((E78*F78),2) -> 3346.4
A79: 8 | B79: анализ 56 | C79: Натоварване на отпадъци на транспорт с багер | D79: м3 | E79: 90.24 | F79: ='Ед. Цени'!F76 -> 1.78 | G79: =ROUND((E79*F79),2) -> 160.63
A80: 9 | B80: анализ 57 | C80: Извозване на асфалтови отпадъци на 80 км | D80: т | E80: 131.6 | F80: ='Ед. Цени'!F77 -> 21.54 | G80: =ROUND((E80*F80),2) -> 2834.66
A81: 10 | B81: анализ 58 | C81: Демонтаж бордюри | D81: м | E81: 250 | F81: ='Ед. Цени'!F78 -> 6.93 | G81: =ROUND((E81*F81),2) -> 1732.5
A82: 11 | B82: анализ 59 | C82: Доставка и монтаж на бетонови бордюри 15/25/50 | D82: м | E82: 250 | F82: ='Ед. Цени'!F79 -> 27.54 | G82: =ROUND((E82*F82),2) -> 6885
...

Sheet кл.I.4
A1: Обект: Реконструкция на компрометирани участъци от водопроводната мрежа в с.Апарухово, Общ.Дългопол- етап 2
A2: Възложител: Община Дългопол
A4: KОЛИЧЕСТВЕНО- СТОЙНОСТНА СМЕТКА - клон I.4 /о.т. 89 до о.т.83/
A8: № | C8: Вид СМР | D8: М-ка | E8: Количество | F8: Ед. цена | G8: Стойност
A11: 1 | C11: 2 | D11: 3 | E11: 4 | F11: 5 | G11: 6
A12: I. ЧАСТ ВОДОСНАБДЯВАНЕ
A13: 1 | B13: анализ 1 | C13: Рязане с фугорез на асфалтова настилка | D13: л.м. | E13: 267.6 | F13: ='Ед. Цени'!F21 -> 3.53 | G13: =ROUND((E13*F13),2) -> 944.63
A14: 2 | B14: анализ 2 | C14: Разваляне асфалтова настилка | D14: м2 | E14: 187.32 | F14: ='Ед. Цени'!F22 -> 6.89 | G14: =ROUND((E14*F14),2) -> 1290.63
A15: 3 | B15: анализ 3 | C15: Изкоп с багер на отвал ЗП неукрепен - спада се от т.4 | D15: м3 | E15: 176.83281 | F15: ='Ед. Цени'!F23 -> 5.5 | G15: =ROUND((E15*F15),2) -> 972.58
A16: 4 | B16: Анализ 65 | C16: Изкоп с дълб. до 2м. ръчно - 30% от машинния | D16: м3 | E16: 75.78549 | F16: ='Ед. Цени'!F85 -> 24.35 | G16: =ROUND((E16*F16),2) -> 1845.38
A17: 5 | B17: анализ 5 | C17: Прехвърляне на изкопана земна маса на 2,00 м вертикално и хоризонтално | D17: м3 | E17: 75.78549 | F17: ='Ед. Цени'!F25 -> 12.47 | G17: =ROUND((E17*F17),2) -> 945.05
A18: 6 | B18: анализ 6 | C18: Натоварване излишната пръст с багер на самосвал | D18: м3 | E18: 252.6183 | F18: ='Ед. Цени'!F26 -> 2.79 | G18: =ROUND((E18*F18),2) -> 704.81
A19: 7 | B19: анализ 7 | C19: Разриване с булдозер на земни маси | D19: м3 | E19: 252.6183 | F19: ='Ед. Цени'!F27 -> 1.98 | G19: =ROUND((E19*F19),2) -> 500.18
A20: 8 | B20: анализ 8 | C20: Превоз на земни маси със самосвал до 5км. | D20: м3 | E20: 252.6183 | F20: ='Ед. Цени'!F28 -> 2.79 | G20: =ROUND((E20*F20),2) -> 704.81
A21: 9 | B21: анализ 9 | C21: Неплътно укрепване и разкрепване на изкопи | D21: м2 | E21: 457.596 | F21: ='Ед. Цени'!F29 -> 2.42 | G21: =ROUND((E21*F21),2) -> 1107.38
A22: 10 | B22: анализ 10 | C22: Доставка на пясък със самосвал на 10км. | D22: м3 | E22: 73.865 | F22: ='Ед. Цени'!F30 -> 19.04 | G22: =ROUND((E22*F22),2) -> 1406.39
A23: 11 | B23: анализ 11 | C23: Превоз с ръчни колички на пясък на 50м | D23: м3 | E23: 73.865 | F23: ='Ед. Цени'!F31 -> 6.14 | G23: =ROUND((E23*F23),2) -> 453.53
A24: 12 | B24: анализ 12 | C24: Подложка от пясък 10см. | D24: м3 | E24: 14.773 | F24: ='Ед. Цени'!F32 -> 8.17 | G24: =ROUND((E24*F24),2) -> 120.7
A25: 13 | B25: анализ 13 | C25: Засипване на тръби с пясък - 40см. | D25: м3 | E25: 59.092 | F25: ='Ед. Цени'!F33 -> 4.75 | G25: =ROUND((E25*F25),2) -> 280.69
A26: 14 | B26: анализ 14 | C26: Уплътняване на пясък с пневматична трамбовка | D26: м3 | E26: 73.865 | F26: ='Ед. Цени'!F34 -> 3.66 | G26: =ROUND((E26*F26),2) -> 270.35
A27: 15 | B27: анализ 15 | C27: Доставка на нестандартна скална маса от кариера на 5км | D27: м3 | E27: 119.8813 | F27: ='Ед. Цени'!F35 -> 17.82 | G27: =ROUND((E27*F27),2) -> 2136.28
A28: 16 | B28: анализ 16 | C28: Превоз с ръчни колички на скална маса на 50м | D28: м3 | E28: 119.8813 | F28: ='Ед. Цени'!F36 -> 6.14 | G28: =ROUND((E28*F28),2) -> 736.07
... A38: 26 | B38: анализ 26 | C38: ВС ф125/1" | D38: бр. | E38: 4 | F38: ='Ед. Цени'!F46 -> 72.23 | G38: =ROUND((E38*F38),2) -> 288.92
A39: 27 | B39: Анализ 66 | C39: Дъга ф125/21 | D39: бр. | E39: 1 | F39: ='Ед. Цени'!F86 -> 49.94 | G39: =ROUND((E39*F39),2) -> 49.94
A40: 28 | B40: анализ 28 | C40: Заварка ф125 | D40: бр. | E40: 13.316667 | F40: ='Ед. Цени'!F48 -> 18.67 | G40: =ROUND((E40*F40),2) -> 248.62
A41: 29 | B41: анализ 29 | C41: Заварка ф90 | D41: бр. | E41: 2 | F41: ='Ед. Цени'!F49 -> 15.4 | G41: =ROUND((E41*F41),2) -> 30.8
A42: 30 | B42: анализ 30 | C42: Ко ф32/1" | D42: бр. | E42: 4 | F42: ='Ед. Цени'!F50 -> 15.9 | G42: =ROUND((E42*F42),2) -> 63.6
A43: 31 | B43: анализ 31 | C43: ПМ ф32/1" | D43: бр. | E43: 4 | F43: ='Ед. Цени'!F51 -> 18.32 | G43: =ROUND((E43*F43),2) -> 73.28
A44: 32 | B44: анализ 32 | C44: ПП. Фл. ф90 | D44: бр. | E44: 1 | F44: ='Ед. Цени'!F52 -> 35.82 | G44: =ROUND((E44*F44),2) -> 35.82
A45: 33 | B45: анализ 33 | C45: ПХ ф70/80 | D45: бр. | E45: 1 | F45: ='Ед. Цени'!F53 -> 324.5 | G45: =ROUND((E45*F45),2) -> 324.5
A46: 34 | B46: анализ 34 | C46: Св. Фл. ф80 | D46: бр. | E46: 1 | F46: ='Ед. Цени'!F54 -> 39.45 | G46: =ROUND((E46*F46),2) -> 39.45
A47: 35 | B47: анализ 35 | C47: СК ф80 с охр. гарн. | D47: бр. | E47: 1 | F47: ='Ед. Цени'!F55 -> 150.7 | G47: =ROUND((E47*F47),2) -> 150.7
A48: 36 | B48: анализ 36 | C48: ТН ф125/ф90 | D48: бр. | E48: 2 | F48: ='Ед. Цени'!F56 -> 65.4 | G48: =ROUND((E48*F48),2) -> 130.8
A49: 37 | B49: анализ 37 | C49: ТСК ф1" | D49: бр. | E49: 4 | F49: ='Ед. Цени'!F57 -> 132.99 | G49: =ROUND((E49*F49),2) -> 531.96
A50: 38 | B50: анализ 38 | C50: ФС Ф80 | D50: бр. | E50: 1 | F50: ='Ед. Цени'!F58 -> 39.45 | G50: =ROUND((E50*F50),2) -> 39.45
A51: 39 | B51: анализ 39 | C51: Хидравлично изпитване на водопровод | D51: л.м. | E51: 134.3 | F51: ='Ед. Цени'!F59 -> 1.78 | G51: =ROUND((E51*F51),2) -> 239.05
... A56: 44 | B56: анализ 44 | C56: Демонтаж и възстановяване на улични бордюри за СВО и ПХ | D56: л.м. | E56: 10 | F56: ='Ед. Цени'!F64 -> 8.95 | G56: =ROUND((E56*F56),2) -> 89.5
A57: 45 | B57: Анализ 67 | C57: Демонтаж и възстановяване на тротоарни плочки за СВО и ПХ | D57: м2 | E57: 10 | F57: ='Ед. Цени'!F87 -> 13.08 | G57: =ROUND((E57*F57),2) -> 130.8
A58: 46 | B58: анализ 45 | C58: Доставка, полагане и валиране каменна фракция 35/75 с Н=40см | D58: м3 | E58: 74.928 | F58: ='Ед. Цени'!F65 -> 18.94 | G58: =ROUND((E58*F58),2) -> 1419.14
A59: 47 | B59: анализ 46 | C59: Битумна разливка | D59: м2 | E59: 187.32 | F59: ='Ед. Цени'!F66 -> 1.77 | G59: =ROUND((E59*F59),2) -> 331.56
...

Sheet кл.I.5
A1: Обект: Реконструкция на компрометирани участъци от водопроводната мрежа в с.Апарухово, Общ.Дългопол- етап 2
A2: Възложител: Община Дългопол
A4: KОЛИЧЕСТВЕНО- СТОЙНОСТНА СМЕТКА - клон I.5 /о.т. 83 до о.т.126/
A7: № | C7: Вид СМР | D7: М-ка | E7: Количество | F7: Ед. цена | G7: Стойност
A10: 1 | C10: 2 | D10: 3 | E10: 4 | F10: 5 | G10: 6
A11: I. ЧАСТ ВОДОСНАБДЯВАНЕ
A12: 1 | B12: анализ 1 | C12: Рязане с фугорез на асфалтова настилка | D12: л.м. | E12: 73.4 | F12: ='Ед. Цени'!F21 -> 3.53 | G12: =ROUND((E12*F12),2) -> 259.1
A13: 2 | B13: анализ 2 | C13: Разваляне асфалтова настилка | D13: м2 | E13: 51.38 | F13: ='Ед. Цени'!F22 -> 6.89 | G13: =ROUND((E13*F13),2) -> 354.01
A14: 3 | B14: анализ 3 | C14: Изкоп с багер на отвал ЗП неукрепен - спада се от т.4 | D14: м3 | E14: 48.32289 | F14: ='Ед. Цени'!F23 -> 5.5 | G14: =ROUND((E14*F14),2) -> 265.78
A15: 4 | B15: Анализ 65 | C15: Изкоп с дълб. до 2м. ръчно - 30% от машинния | D15: м3 | E15: 20.70981 | F15: ='Ед. Цени'!F85 -> 24.35 | G15: =ROUND((E15*F15),2) -> 504.28
A16: 5 | B16: анализ 5 | C16: Прехвърляне на изкопана земна маса на 2,00 м вертикално и хоризонтално | D16: м3 | E16: 20.70981 | F16: ='Ед. Цени'!F25 -> 12.47 | G16: =ROUND((E16*F16),2) -> 258.25
A17: 6 | B17: анализ 6 | C17: Натоварване излишната пръст с багер на самосвал | D17: м3 | E17: 69.0327 | F17: ='Ед. Цени'!F26 -> 2.79 | G17: =ROUND((E17*F17),2) -> 192.6
A18: 7 | B18: анализ 7 | C18: Разриване с булдозер на земни маси | D18: м3 | E18: 69.0327 | F18: ='Ед. Цени'!F27 -> 1.98 | G18: =ROUND((E18*F18),2) -> 136.68
A19: 8 | B19: анализ 8 | C19: Превоз на земни маси със самосвал до 5км. | D19: м3 | E19: 69.0327 | F19: ='Ед. Цени'!F28 -> 2.79 | G19: =ROUND((E19*F19),2) -> 192.6
A20: 9 | B20: анализ 9 | C20: Неплътно укрепване и разкрепване на изкопи | D20: м2 | E20: 125.514 | F20: ='Ед. Цени'!F29 -> 2.42 | G20: =ROUND((E20*F20),2) -> 303.74
A21: 10 | B21: анализ 10 | C21: Доставка на пясък със самосвал на 10км. | D21: м3 | E21: 20.185 | F21: ='Ед. Цени'!F30 -> 19.04 | G21: =ROUND((E21*F21),2) -> 384.32
A22: 11 | B22: анализ 11 | C22: Превоз с ръчни колички на пясък на 50м | D22: м3 | E22: 20.185 | F22: ='Ед. Цени'!F31 -> 6.14 | G22: =ROUND((E22*F22),2) -> 123.94
A23: 12 | B23: анализ 12 | C23: Подложка от пясък 10см. | D23: м3 | E23: 4.037 | F23: ='Ед. Цени'!F32 -> 8.17 | G23: =ROUND((E23*F23),2) -> 32.98
A24: 13 | B24: анализ 13 | C24: Засипване на тръби с пясък - 40см. | D24: м3 | E24: 16.148 | F24: ='Ед. Цени'!F33 -> 4.75 | G24: =ROUND((E24*F24),2) -> 76.7
A25: 14 | B25: анализ 14 | C25: Уплътняване на пясък с пневматична трамбовка | D25: м3 | E25: 20.185 | F25: ='Ед. Цени'!F34 -> 3.66 | G25: =ROUND((E25*F25),2) -> 73.88
A26: 15 | B26: анализ 15 | C26: Доставка на нестандартна скална маса от кариера на 5км | D26: м3 | E26: 32.6997 | F26: ='Ед. Цени'!F35 -> 17.82 | G26: =ROUND((E26*F26),2) -> 582.71
A27: 16 | B27: анализ 16 | C27: Превоз с ръчни колички на скална маса на 50м | D27: м3 | E27: 32.6997 | F27: ='Ед. Цени'!F36 -> 6.14 | G27: =ROUND((E27*F27),2) -> 200.78
... A33: 22 | B33: анализ 22 | C33: Полагане ПЕВП тръби ø125мм. | D33: л.м. | E33: 29.7 | F33: ='Ед. Цени'!F42 -> 30.97 | G33: =ROUND((E33*F33),2) -> 919.81
A34: 23 | B34: анализ 24 | C34: Полагане ПЕВП тръби ø32мм. | D34: л.м. | E34: 7 | F34: ='Ед. Цени'!F44 -> 7.79 | G34: =ROUND((E34*F34),2) -> 54.53
A35: 24 | B35: анализ 26 | C35: ВС ф125/1" | D35: бр. | E35: 1 | F35: ='Ед. Цени'!F46 -> 72.23 | G35: =ROUND((E35*F35),2) -> 72.23
A36: 25 | B36: анализ 25 | C36: БОБ | D36: бр. | E36: 4 | F36: ='Ед. Цени'!F45 -> 14.87 | G36: =ROUND((E36*F36),2) -> 59.48
A37: 26 | B37: Анализ 68 | C37: Дъга ф125/15 | D37: бр. | E37: 1 | F37: ='Ед. Цени'!F86 -> 49.94 | G37: =ROUND((E37*F37),2) -> 49.94
A38: 27 | B38: Анализ 69 | C38: Заварка ф110 | D38: бр. | E38: 3 | F38: ='Ед. Цени'!F89 -> 16.19 | G38: =ROUND((E38*F38),2) -> 48.57
A39: 28 | B39: анализ 28 | C39: Заварка ф125 | D39: бр. | E39: 6.475 | F39: ='Ед. Цени'!F48 -> 18.67 | G39: =ROUND((E39*F39),2) -> 120.89
A40: 29 | B40: анализ 30 | C40: Ко ф32/1" | D40: бр. | E40: 1 | F40: ='Ед. Цени'!F50 -> 15.9 | G40: =ROUND((E40*F40),2) -> 15.9
A41: 30 | B41: Анализ 70 | C41: Коляно ф125/60 | D41: бр. | E41: 2 | F41: ='Ед. Цени'!F90 -> 52.01 | G41: =ROUND((E41*F41),2) -> 104.02
A42: 31 | B42: Анализ 71 | C42: Намалител ф125/ф110 | D42: бр. | E42: 1 | F42: ='Ед. Цени'!F91 -> 39.91 | G42: =ROUND((E42*F42),2) -> 39.91
A43: 32 | B43: анализ 31 | C43: ПМ ф32/1" | D43: бр. | E43: 1 | F43: ='Ед. Цени'!F51 -> 18.32 | G43: =ROUND((E43*F43),2) -> 18.32
A44: 33 | B44: Анализ 72 | C44: Преход Фл. ф125/ф125 | D44: бр. | E44: 2 | F44: ='Ед. Цени'!F92 -> 51.5 | G44: =ROUND((E44*F44),2) -> 103
A45: 34 | B45: Анализ 73 | C45: СК ф125 с охр. гарн. | D45: бр. | E45: 1 | F45: ='Ед. Цени'!F93 -> 167.64 | G45: =ROUND((E45*F45),2) -> 167.64
A46: 35 | B46: Анализ 74 | C46: Т ф110/ф110 | D46: бр. | E46: 1 | F46: ='Ед. Цени'!F94 -> 58.5 | G46: =ROUND((E46*F46),2) -> 58.5
A47: 36 | B47: анализ 37 | C47: ТСК ф1" | D47: бр. | E47: 1 | F47: ='Ед. Цени'!F57 -> 132.99 | G47: =ROUND((E47*F47),2) -> 132.99
A48: 37 | B48: Анализ 75 | C48: Св. Фл. ф125 | D48: бр. | E48: 2 | F48: ='Ед. Цени'!F95 -> 47.92 | G48: =ROUND((E48*F48),2) -> 95.84
A49: 38 | B49: Анализ 76 | C49: ФС Ф125 | D49: бр. | E49: 2 | F49: ='Ед. Цени'!F96 -> 47.92 | G49: =ROUND((E49*F49),2) -> 95.84
A50: 39 | B50: анализ 39 | C50: Хидравлично изпитване на водопровод | D50: л.м. | E50: 36.7 | F50: ='Ед. Цени'!F59 -> 1.78 | G50: =ROUND((E50*F50),2) -> 65.33
...

Sheet кл.I.6
A1: Обект: Реконструкция на компрометирани участъци от водопроводната мрежа в с.Апарухово, Общ.Дългопол- етап 2
A2: Възложител: Община Дългопол
A4: KОЛИЧЕСТВЕНО- СТОЙНОСТНА СМЕТКА- клон I.6 /о.т. 126 до о.т.127/
A7: № | C7: Вид СМР | D7: М-ка | E7: Количество | F7: Ед. цена | G7: Стойност
A10: 1 | C10: 2 | D10: 3 | E10: 4 | F10: 5 | G10: 6
A11: I. ЧАСТ ВОДОСНАБДЯВАНЕ
A12: 1 | B12: анализ 1 | C12: Рязане с фугорез на асфалтова настилка | D12: л.м. | E12: 244 | F12: ='Ед. Цени'!F21 -> 3.53 | G12: =ROUND((E12*F12),2) -> 861.32
A13: 2 | B13: анализ 2 | C13: Разваляне асфалтова настилка | D13: м2 | E13: 170.8 | F13: ='Ед. Цени'!F22 -> 6.89 | G13: =ROUND((E13*F13),2) -> 1176.81
A14: 3 | B14: анализ 3 | C14: Изкоп с багер на отвал ЗП неукрепен - спада се от т.4 | D14: м3 | E14: 160.6374 | F14: ='Ед. Цени'!F23 -> 5.5 | G14: =ROUND((E14*F14),2) -> 883.51
A15: 4 | B15: Анализ 65 | C15: Изкоп с дълб. до 2м. ръчно - 30% от машинния | D15: м3 | E15: 68.8446 | F15: ='Ед. Цени'!F85 -> 24.35 | G15: =ROUND((E15*F15),2) -> 1676.37
A16: 5 | B16: анализ 5 | C16: Прехвърляне на изкопана земна маса на 2,00 м вертикално и хоризонтално | D16: м3 | E16: 68.8446 | F16: ='Ед. Цени'!F25 -> 12.47 | G16: =ROUND((E16*F16),2) -> 858.49
A17: 6 | B17: анализ 6 | C17: Натоварване излишната пръст с багер на самосвал | D17: м3 | E17: 229.482 | F17: ='Ед. Цени'!F26 -> 2.79 | G17: =ROUND((E17*F17),2) -> 640.25
A18: 7 | B18: анализ 7 | C18: Разриване с булдозер на земни маси | D18: м3 | E18: 229.482 | F18: ='Ед. Цени'!F27 -> 1.98 | G18: =ROUND((E18*F18),2) -> 454.37
A19: 8 | B19: анализ 8 | C19: Превоз на земни маси със самосвал до 5км. | D19: м3 | E19: 229.482 | F19: ='Ед. Цени'!F28 -> 2.79 | G19: =ROUND((E19*F19),2) -> 640.25
A20: 9 | B20: анализ 9 | C20: Неплътно укрепване и разкрепване на изкопи | D20: м2 | E20: 417.24 | F20: ='Ед. Цени'!F29 -> 2.42 | G20: =ROUND((E20*F20),2) -> 1009.72
A21: 10 | B21: анализ 10 | C21: Доставка на пясък със самосвал на 10км. | D21: м3 | E21: 67.1 | F21: ='Ед. Цени'!F30 -> 19.04 | G21: =ROUND((E21*F21),2) -> 1277.58
A22: 11 | B22: анализ 11 | C22: Превоз с ръчни колички на пясък на 50м | D22: м3 | E22: 67.1 | F22: ='Ед. Цени'!F31 -> 6.14 | G22: =ROUND((E22*F22),2) -> 411.99
A23: 12 | B23: анализ 12 | C23: Подложка от пясък 10см. | D23: м3 | E23: 13.42 | F23: ='Ед. Цени'!F32 -> 8.17 | G23: =ROUND((E23*F23),2) -> 109.64
A24: 13 | B24: анализ 13 | C24: Засипване на тръби с пясък - 40см. | D24: м3 | E24: 53.68 | F24: ='Ед. Цени'!F33 -> 4.75 | G24: =ROUND((E24*F24),2) -> 254.98
A25: 14 | B25: анализ 14 | C25: Уплътняване на пясък с пневматична трамбовка | D25: м3 | E25: 67.1 | F25: ='Ед. Цени'!F34 -> 3.66 | G25: =ROUND((E25*F25),2) -> 245.59
A26: 15 | B26: анализ 15 | C26: Доставка на нестандартна скална маса от кариера на 5км | D26: м3 | E26: 108.702 | F26: ='Ед. Цени'!F35 -> 17.82 | G26: =ROUND((E26*F26),2) -> 1937.07
A27: 16 | B27: анализ 16 | C27: Превоз с ръчни колички на скална маса на 50м | D27: м3 | E27: 108.702 | F27: ='Ед. Цени'!F36 -> 6.14 | G27: =ROUND((E27*F27),2) -> 667.43
... A32: 21 | B32: анализ 21 | C32: Извозване асфалтови отпадъци със самосвал до 5км. | D32: м3 | E32: 17.08 | F32: ='Ед. Цени'!F41 -> 2.3 | G32: =ROUND((E32*F32),2) -> 39.28
A33: 22 | B33: Анализ 77 | C33: Полагане ПЕВП тръби ø110мм. | D33: л.м. | E33: 108 | F33: ='Ед. Цени'!F97 -> 27.46 | G33: =ROUND((E33*F33),2) -> 2965.68
A34: 24 | B34: анализ 24 | C34: Полагане ПЕВП тръби ø32мм. | D34: л.м. | E34: 14 | F34: ='Ед. Цени'!F44 -> 7.79 | G34: =ROUND((E34*F34),2) -> 109.06
A35: 25 | B35: анализ 25 | C35: БОБ | D35: бр. | E35: 1 | F35: ='Ед. Цени'!F45 -> 14.87 | G35: =ROUND((E35*F35),2) -> 14.87
A36: 26 | B36: Анализ 78 | C36: ВС ф110/1" | D36: бр. | E36: 2 | F36: ='Ед. Цени'!F98 -> 64.97 | G36: =ROUND((E36*F36),2) -> 129.94
A37: 27 | B37: Анализ 69 | C37: Заварка ф110 | D37: бр. | E37: 12 | F37: ='Ед. Цени'!F89 -> 16.19 | G37: =ROUND((E37*F37),2) -> 194.28
A38: 28 | B38: анализ 30 | C38: Ко ф32/1" | D38: бр. | E38: 2 | F38: ='Ед. Цени'!F50 -> 15.9 | G38: =ROUND((E38*F38),2) -> 31.8
A39: 29 | B39: анализ 31 | C39: ПМ ф32/1" | D39: бр. | E39: 2 | F39: ='Ед. Цени'!F51 -> 18.32 | G39: =ROUND((E39*F39),2) -> 36.64
A40: 30 | B40: Анализ 74 | C40: Т ф110/ф110 | D40: бр. | E40: 1 | F40: ='Ед. Цени'!F94 -> 58.5 | G40: =ROUND((E40*F40),2) -> 58.5
A41: 31 | B41: анализ 37 | C41: ТСК ф1" | D41: бр. | E41: 2 | F41: ='Ед. Цени'!F57 -> 132.99 | G41: =ROUND((E41*F41),2) -> 265.98
A42: 32 | B42: анализ 39 | C42: Хидравлично изпитване на водопровод | D42: л.м. | E42: 122 | F42: ='Ед. Цени'!F59 -> 1.78 | G42: =ROUND((E42*F42),2) -> 217.16
A43: 33 | B43: анализ 40 | C43: Дезинфекция на водопровод | D43: л.м. | E43: 122 | F43: ='Ед. Цени'!F60 -> 1.61 | G43: =ROUND((E43*F43),2) -> 196.42
A44: 34 | B44: анализ 41 | C44: Укрепване на гърне за СК | D44: бр. | E44: 2 | F44: ='Ед. Цени'!F61 -> 10.45 | G44: =ROUND((E44*F44),2) -> 20.9
A45: 35 | B45: анализ 42 | C45: Доставка и монтаж на табели за СК | D45: бр. | E45: 0 | F45: ='Ед. Цени'!F62 -> 18.52 | G45: =ROUND((E45*F45),2) -> 0
A46: 36 | B46: анализ 44 | C46: Демонтаж и възстановяване на улични бордюри за СВО и ПХ | D46: л.м. | E46: 4 | F46: ='Ед. Цени'!F64 -> 8.95 | G46: =ROUND((E46*F46),2) -> 35.8
A47: 37 | B47: Анализ 67 | C47: Демонтаж и възстановяване на тротоарни плочки за СВО и ПХ | D47: м2 | E47: 4 | F47: ='Ед. Цени'!F87 -> 13.08 | G47: =ROUND((E47*F47),2) -> 52.32
A48: 38 | B48: анализ 45 | C48: Доставка, полагане и валиране каменна фракция 35/75 с Н=40см | D48: м3 | E48: 68.32 | F48: ='Ед. Цени'!F65 -> 18.94 | G48: =ROUND((E48*F48),2) -> 1293.98
A49: 39 | B49: анализ 46 | C49: Битумна разливка | D49: м2 | E49: 170.8 | F49: ='Ед. Цени'!F66 -> 1.77 | G49: =ROUND((E49*F49),2) -> 302.32
...

Sheet кл.I.7
A1: Обект: Реконструкция на компрометирани участъци от водопроводната мрежа в с.Апарухово, Общ.Дългопол- етап 2
A2: Възложител: Община Дългопол
A4: KОЛИЧЕСТВЕНО- СТОЙНОСТНА СМЕТКА - клон I.7 /о.т. 127 до о.т.82/
A7: № | C7: Вид СМР | D7: М-ка | E7: Количество | F7: Ед. цена | G7: Стойност
A10: 1 | C10: 2 | D10: 3 | E10: 4 | F10: 5 | G10: 6
A11: I. ЧАСТ ВОДОСНАБДЯВАНЕ
A12: 1 | B12: анализ 1 | C12: Рязане с фугорез на асфалтова настилка | D12: л.м. | E12: 50.8 | F12: ='Ед. Цени'!F21 -> 3.53 | G12: =ROUND((E12*F12),2) -> 179.32
A13: 2 | B13: анализ 2 | C13: Разваляне асфалтова настилка | D13: м2 | E13: 35.56 | F13: ='Ед. Цени'!F22 -> 6.89 | G13: =ROUND((E13*F13),2) -> 245.01
A14: 3 | B14: анализ 3 | C14: Изкоп с багер на отвал ЗП неукрепен - спада се от т.4 | D14: м3 | E14: 33.44418 | F14: ='Ед. Цени'!F23 -> 5.5 | G14: =ROUND((E14*F14),2) -> 183.94
A15: 4 | B15: Анализ 65 | C15: Изкоп с дълб. до 2м. ръчно - 30% от машинния | D15: м3 | E15: 14.33322 | F15: ='Ед. Цени'!F85 -> 24.35 | G15: =ROUND((E15*F15),2) -> 349.01
A16: 5 | B16: анализ 5 | C16: Прехвърляне на изкопана земна маса на 2,00 м вертикално и хоризонтално | D16: м3 | E16: 14.33322 | F16: ='Ед. Цени'!F25 -> 12.47 | G16: =ROUND((E16*F16),2) -> 178.74
A17: 6 | B17: анализ 6 | C17: Натоварване излишната пръст с багер на самосвал | D17: м3 | E17: 47.7774 | F17: ='Ед. Цени'!F26 -> 2.79 | G17: =ROUND((E17*F17),2) -> 133.3
A18: 7 | B18: анализ 7 | C18: Разриване с булдозер на земни маси | D18: м3 | E18: 47.7774 | F18: ='Ед. Цени'!F27 -> 1.98 | G18: =ROUND((E18*F18),2) -> 94.6
A19: 8 | B19: анализ 8 | C19: Превоз на земни маси със самосвал до 5км. | D19: м3 | E19: 47.7774 | F19: ='Ед. Цени'!F28 -> 2.79 | G19: =ROUND((E19*F19),2) -> 133.3
A20: 9 | B20: анализ 9 | C20: Неплътно укрепване и разкрепване на изкопи | D20: м2 | E20: 86.868 | F20: ='Ед. Цени'!F29 -> 2.42 | G20: =ROUND((E20*F20),2) -> 210.22
A21: 10 | B21: анализ 10 | C21: Доставка на пясък със самосвал на 10км. | D21: м3 | E21: 13.97 | F21: ='Ед. Цени'!F30 -> 19.04 | G21: =ROUND((E21*F21),2) -> 265.99
A22: 11 | B22: анализ 11 | C22: Превоз с ръчни колички на пясък на 50м | D22: м3 | E22: 13.97 | F22: ='Ед. Цени'!F31 -> 6.14 | G22: =ROUND((E22*F22),2) -> 85.78
A23: 12 | B23: анализ 12 | C23: Подложка от пясък 10см. | D23: м3 | E23: 2.794 | F23: ='Ед. Цени'!F32 -> 8.17 | G23: =ROUND((E23*F23),2) -> 22.83
A24: 13 | B24: анализ 13 | C24: Засипване на тръби с пясък - 40см. | D24: м3 | E24: 11.176 | F24: ='Ед. Цени'!F33 -> 4.75 | G24: =ROUND((E24*F24),2) -> 53.09
A25: 14 | B25: анализ 14 | C25: Уплътняване на пясък с пневматична трамбовка | D25: м3 | E25: 13.97 | F25: ='Ед. Цени'!F34 -> 3.66 | G25: =ROUND((E25*F25),2) -> 51.13
A26: 15 | B26: анализ 15 | C26: Доставка на нестандартна скална маса от кариера на 5км | D26: м3 | E26: 16.4338 | F26: ='Ед. Цени'!F35 -> 17.82 | G26: =ROUND((E26*F26),2) -> 292.85
A27: 16 | B27: анализ 16 | C27: Превоз с ръчни колички на скална маса на 50м | D27: м3 | E27: 16.4338 | F27: ='Ед. Цени'!F36 -> 6.14 | G27: =ROUND((E27*F27),2) -> 100.9
... A32: 21 | B32: анализ 21 | C32: Извозване асфалтови отпадъци със самосвал до 5км. | D32: м3 | E32: 3.556 | F32: ='Ед. Цени'!F41 -> 2.3 | G32: =ROUND((E32*F32),2) -> 8.18
A33: 22 | B33: Анализ 77 | C33: Полагане ПЕВП тръби ø110мм. | D33: л.м. | E33: 25.4 | F33: ='Ед. Цени'!F97 -> 27.46 | G33: =ROUND((E33*F33),2) -> 697.48
A34: 23 | B34: Анализ 79 | C34: Коляно ф110/90 | D34: бр. | E34: 1 | F34: ='Ед. Цени'!F99 -> 47.17 | G34: =ROUND((E34*F34),2) -> 47.17
A35: 24 | B35: Анализ 80 | C35: ТН ф110/ф90 | D35: бр. | E35: 1 | F35: ='Ед. Цени'!F100 -> 62.13 | G35: =ROUND((E35*F35),2) -> 62.13
A36: 25 | B36: Анализ 69 | C36: Заварка ф110 | D36: бр. | E36: 5.1166667 | F36: ='Ед. Цени'!F89 -> 16.19 | G36: =ROUND((E36*F36),2) -> 82.84
A37: 26 | B37: анализ 25 | C37: БОБ | D37: бр. | E37: 2 | F37: ='Ед. Цени'!F45 -> 14.87 | G37: =ROUND((E37*F37),2) -> 29.74
A38: 27 | B38: анализ 39 | C38: Хидравлично изпитване на водопровод | D38: л.м. | E38: 25.4 | F38: ='Ед. Цени'!F59 -> 1.78 | G38: =ROUND((E38*F38),2) -> 45.21
A39: 28 | B39: анализ 40 | C39: Дезинфекция на водопровод | D39: л.м. | E39: 25.4 | F39: ='Ед. Цени'!F60 -> 1.61 | G39: =ROUND((E39*F39),2) -> 40.89
A40: 29 | B40: анализ 45 | C40: Доставка, полагане и валиране каменна фракция 35/75 с Н=40см | D40: м3 | E40: 14.224 | F40: ='Ед. Цени'!F65 -> 18.94 | G40: =ROUND((E40*F40),2) -> 269.4
A41: 30 | B41: анализ 46 | C41: Битумна разливка | D41: м2 | E41: 35.56 | F41: ='Ед. Цени'!F66 -> 1.77 | G41: =ROUND((E41*F41),2) -> 62.94
A42: 31 | B42: Анализ 81 | C42: Доставка и полагане на неуплътен асфалт 5 см | D42: тон | E42: 4.2672 | F42: ='Ед. Цени'!F101 -> 125.37 | G42: =ROUND((E42*F42),2) -> 534.98
A43: 32 | B43: анализ 48 | C43: Доставка и монтажна сигнална лента над водопровода | D43: л.м. | E43: 25.4 | F43: ='Ед. Цени'!F68 -> 0.92 | G43: =ROUND((E43*F43),2) -> 23.37
A44: 33 | B44: анализ 49 | C44: Доставка и монтажна детекторна лента над водопровода | D44: л.м. | E44: 25.4 | F44: ='Ед. Цени'!F69 -> 1.41 | G44: =ROUND((E44*F44),2) -> 35.81
C45: Общо за част Водоснабдяване: | G45: =SUM(G12:G44) -> 4613.07
A46: II. ЧАСТ ВЪЗСТАНОВЯВАНЕ НА НАСТИЛКАТА
A47: 1 | B47: анализ 50 | C47: Изкоп на земни почви с багер на транспорт | D47: м3 | E47: 5.08 | F47: ='Ед. Цени'!F70 -> 7.8 | G47: =ROUND((E47*F47),2) -> 39.62
A48: 2 | B48: анализ 51 | C48: Изкоп ръчен в земни почви | D48: м3 | E48: 2.17 | F48: ='Ед. Цени'!F71 -> 16.63 | G48: =ROUND((E48*F48),2) -> 36.09
A49: 3 | B49: анализ 52 | C49: Почистване на реголи и настилки от кал | D49: м2 | E49: 12 | F49: ='Ед. Цени'!F72 -> 6.09 | G49: =ROUND((E49*F49),2) -> 73.08
...

Sheet кл.I.8
A1: Обект: Реконструкция на компрометирани участъци от водопроводната мрежа в с.Апарухово, Общ.Дългопол- етап 2
A2: Възложител: Община Дългопол
A4: KОЛИЧЕСТВЕНО- СТОЙНОСТНА СМЕТКА - клон I.8 /о.т. 82 до о.т.84/
A7: № | C7: Вид СМР | D7: М-ка | E7: Количество | F7: Ед. цена | G7: Стойност
A10: 1 | C10: 2 | D10: 3 | E10: 4 | F10: 5 | G10: 6
A11: I. ЧАСТ ВОДОСНАБДЯВАНЕ
A12: 1 | B12: анализ 1 | C12: Рязане с фугорез на асфалтова настилка | D12: л.м. | E12: 388.2 | F12: ='Ед. Цени'!F21 -> 3.53 | G12: =ROUND((E12*F12),2) -> 1370.35
A13: 2 | B13: анализ 2 | C13: Разваляне асфалтова настилка | D13: м2 | E13: 271.74 | F13: ='Ед. Цени'!F22 -> 6.89 | G13: =ROUND((E13*F13),2) -> 1872.29
A14: 3 | B14: анализ 3 | C14: Изкоп с багер на отвал ЗП неукрепен - спада се от т.4 | D14: м3 | E14: 255.57147 | F14: ='Ед. Цени'!F23 -> 5.5 | G14: =ROUND((E14*F14),2) -> 1405.64
A15: 4 | B15: Анализ 65 | C15: Изкоп с дълб. до 2м. ръчно - 30% от машинния | D15: м3 | E15: 109.53063 | F15: ='Ед. Цени'!F85 -> 24.35 | G15: =ROUND((E15*F15),2) -> 2667.07
A16: 5 | B16: анализ 5 | C16: Прехвърляне на изкопана земна маса на 2,00 м вертикално и хоризонтално | D16: м3 | E16: 109.53063 | F16: ='Ед. Цени'!F25 -> 12.47 | G16: =ROUND((E16*F16),2) -> 1365.85
A17: 6 | B17: анализ 6 | C17: Натоварване излишната пръст с багер на самосвал | D17: м3 | E17: 365.1021 | F17: ='Ед. Цени'!F26 -> 2.79 | G17: =ROUND((E17*F17),2) -> 1018.63
A18: 7 | B18: анализ 7 | C18: Разриване с булдозер на земни маси | D18: м3 | E18: 365.1021 | F18: ='Ед. Цени'!F27 -> 1.98 | G18: =ROUND((E18*F18),2) -> 722.9
A19: 8 | B19: анализ 8 | C19: Превоз на земни маси със самосвал до 5км. | D19: м3 | E19: 365.1021 | F19: ='Ед. Цени'!F28 -> 2.79 | G19: =ROUND((E19*F19),2) -> 1018.63
A20: 9 | B20: анализ 9 | C20: Неплътно укрепване и разкрепване на изкопи | D20: м2 | E20: 663.822 | F20: ='Ед. Цени'!F29 -> 2.42 | G20: =ROUND((E20*F20),2) -> 1606.45
A21: 10 | B21: анализ 10 | C21: Доставка на пясък със самосвал на 10км. | D21: м3 | E21: 106.755 | F21: ='Ед. Цени'!F30 -> 19.04 | G21: =ROUND((E21*F21),2) -> 2032.62
A22: 11 | B22: анализ 11 | C22: Превоз с ръчни колички на пясък на 50м | D22: м3 | E22: 106.755 | F22: ='Ед. Цени'!F31 -> 6.14 | G22: =ROUND((E22*F22),2) -> 655.48
A23: 12 | B23: анализ 12 | C23: Подложка от пясък 10см. | D23: м3 | E23: 21.351 | F23: ='Ед. Цени'!F32 -> 8.17 | G23: =ROUND((E23*F23),2) -> 174.44
A24: 13 | B24: анализ 13 | C24: Засипване на тръби с пясък - 40см. | D24: м3 | E24: 85.404 | F24: ='Ед. Цени'!F33 -> 4.75 | G24: =ROUND((E24*F24),2) -> 405.67
A25: 14 | B25: анализ 14 | C25: Уплътняване на пясък с пневматична трамбовка | D25: м3 | E25: 106.755 | F25: ='Ед. Цени'!F34 -> 3.66 | G25: =ROUND((E25*F25),2) -> 390.72
A26: 15 | B26: анализ 15 | C26: Доставка на нестандартна скална маса от кариера на 5км | D26: м3 | E26: 172.9431 | F26: ='Ед. Цени'!F35 -> 17.82 | G26: =ROUND((E26*F26),2) -> 3081.85
A27: 16 | B27: анализ 16 | C27: Превоз с ръчни колички на скална маса на 50м | D27: м3 | E27: 172.9431 | F27: ='Ед. Цени'!F36 -> 6.14 | G27: =ROUND((E27*F27),2) -> 1061.87
... A32: 21 | B32: анализ 21 | C32: Извозване асфалтови отпадъци със самосвал до 5км. | D32: м3 | E32: 27.174 | F32: ='Ед. Цени'!F41 -> 2.3 | G32: =ROUND((E32*F32),2) -> 62.5
A33: 22 | B33: Анализ 77 | C33: Полагане ПЕВП тръби ø110мм. | D33: л.м. | E33: 134.4 | F33: ='Ед. Цени'!F97 -> 27.46 | G33: =ROUND((E33*F33),2) -> 3690.62
A34: 23 | B34: анализ 24 | C34: Полагане ПЕВП тръби ø32мм. | D34: л.м. | E34: 59.7 | F34: ='Ед. Цени'!F44 -> 7.79 | G34: =ROUND((E34*F34),2) -> 465.06
A35: 24 | B35: анализ 25 | C35: БОБ | D35: бр. | E35: 2 | F35: ='Ед. Цени'!F45 -> 14.87 | G35: =ROUND((E35*F35),2) -> 29.74
A36: 25 | B36: Анализ 78 | C36: ВС ф110/1" | D36: бр. | E36: 9 | F36: ='Ед. Цени'!F98 -> 64.97 | G36: =ROUND((E36*F36),2) -> 584.73
A37: 26 | B37: Анализ 69 | C37: Заварка ф110 | D37: бр. | E37: 14.2 | F37: ='Ед. Цени'!F89 -> 16.19 | G37: =ROUND((E37*F37),2) -> 229.9
A38: 27 | B38: анализ 29 | C38: Заварка ф90 | D38: бр. | E38: 3 | F38: ='Ед. Цени'!F49 -> 15.4 | G38: =ROUND((E38*F38),2) -> 46.2
A39: 28 | B39: анализ 30 | C39: Ко ф32/1" | D39: бр. | E39: 9 | F39: ='Ед. Цени'!F50 -> 15.9 | G39: =ROUND((E39*F39),2) -> 143.1
A40: 29 | B40: Анализ 82 | C40: Намалител ф110/ф90 | D40: бр. | E40: 1 | F40: ='Ед. Цени'!F102 -> 31.44 | G40: =ROUND((E40*F40),2) -> 31.44
A41: 30 | B41: анализ 31 | C41: ПМ ф32/1" | D41: бр. | E41: 9 | F41: ='Ед. Цени'!F51 -> 18.32 | G41: =ROUND((E41*F41),2) -> 164.88
A42: 31 | B42: Анализ 83 | C42: Преход Фл. ф110/ф100 | D42: бр. | E42: 2 | F42: ='Ед. Цени'!F103 -> 40.61 | G42: =ROUND((E42*F42),2) -> 81.22
A43: 32 | B43: Анализ 84 | C43: СК ф100 с охр. гарн. | D43: бр. | E43: 1 | F43: ='Ед. Цени'!F104 -> 156.75 | G43: =ROUND((E43*F43),2) -> 156.75
A44: 33 | B44: Анализ 85 | C44: Т ф90/ф90 | D44: бр. | E44: 1 | F44: ='Ед. Цени'!F105 -> 53.66 | G44: =ROUND((E44*F44),2) -> 53.66
A45: 34 | B45: анализ 37 | C45: ТСК ф1" | D45: бр. | E45: 9 | F45: ='Ед. Цени'!F57 -> 132.99 | G45: =ROUND((E45*F45),2) -> 1196.91
A46: 35 | B46: Анализ 86 | C46: Св. Фл. ф100 | D46: бр. | E46: 2 | F46: ='Ед. Цени'!F106 -> 43.08 | G46: =ROUND((E46*F46),2) -> 86.16
A47: 36 | B47: Анализ 87 | C47: ФС Ф100 | D47: бр. | E47: 2 | F47: ='Ед. Цени'!F107 -> 43.08 | G47: =ROUND((E47*F47),2) -> 86.16
A48: 37 | B48: анализ 39 | C48: Хидравлично изпитване на водопровод | D48: л.м. | E48: 194.1 | F48: ='Ед. Цени'!F59 -> 1.78 | G48: =ROUND((E48*F48),2) -> 345.5
A49: 38 | B49: анализ 40 | C49: Дезинфекция на водопровод | D49: л.м. | E49: 194.1 | F49: ='Ед. Цени'!F60 -> 1.61 | G49: =ROUND((E49*F49),2) -> 312.5
...

Sheet кл.10.1
A1: Обект: Реконструкция на компрометирани участъци от водопроводната мрежа в с.Апарухово, Общ.Дългопол- етап 2
A2: Възложител: Община Дългопол
A4: KОЛИЧЕСТВЕНО- СТОЙНОСТНА СМЕТКА - Клон 10.1 /о.т. 89 до о.т.91/
A6: № | C6: Вид СМР | D6: М-ка | E6: Количество | F6: Ед. цена | G6: Стойност
A9: 1 | C9: 2 | D9: 3 | E9: 4 | F9: 5 | G9: 6
A10: I. ЧАСТ ВОДОСНАБДЯВАНЕ
A11: 1 | B11: анализ 1 | C11: Рязане с фугорез на асфалтова настилка | D11: л.м. | E11: 569.6 | F11: ='Ед. Цени'!F21 -> 3.53 | G11: =ROUND((E11*F11),2) -> 2010.69
A12: 2 | B12: анализ 2 | C12: Разваляне асфалтова настилка | D12: м2 | E12: 398.72 | F12: ='Ед. Цени'!F22 -> 6.89 | G12: =ROUND((E12*F12),2) -> 2747.18
A13: 3 | B13: анализ 3 | C13: Изкоп с багер на отвал ЗП неукрепен - спада се от т.4 | D13: м3 | E13: 374.1122 | F13: ='Ед. Цени'!F23 -> 5.5 | G13: =ROUND((E13*F13),2) -> 2057.62
A14: 4 | B14: Анализ 65 | C14: Изкоп с дълб. до 2м. ръчно - 30% от машинния | D14: м3 | E14: 160.3338 | F14: ='Ед. Цени'!F85 -> 24.35 | G14: =ROUND((E14*F14),2) -> 3904.13
A15: 5 | B15: анализ 5 | C15: Прехвърляне на изкопана земна маса на 2,00 м вертикално и хоризонтално | D15: м3 | E15: 160.3338 | F15: ='Ед. Цени'!F25 -> 12.47 | G15: =ROUND((E15*F15),2) -> 1999.36
A16: 6 | B16: анализ 6 | C16: Натоварване излишната пръст с багер на самосвал | D16: м3 | E16: 534.446 | F16: ='Ед. Цени'!F26 -> 2.79 | G16: =ROUND((E16*F16),2) -> 1491.1
A17: 7 | B17: анализ 7 | C17: Разриване с булдозер на земни маси | D17: м3 | E17: 534.446 | F17: ='Ед. Цени'!F27 -> 1.98 | G17: =ROUND((E17*F17),2) -> 1058.2
A18: 8 | B18: анализ 8 | C18: Превоз на земни маси със самосвал до 5км. | D18: м3 | E18: 534.446 | F18: ='Ед. Цени'!F28 -> 2.79 | G18: =ROUND((E18*F18),2) -> 1491.1
A19: 9 | B19: анализ 9 | C19: Неплътно укрепване и разкрепване на изкопи | D19: м2 | E19: 968.32 | F19: ='Ед. Цени'!F29 -> 2.42 | G19: =ROUND((E19*F19),2) -> 2343.33
A20: 10 | B20: анализ 10 | C20: Доставка на пясък със самосвал на 10км. | D20: м3 | E20: 157.19 | F20: ='Ед. Цени'!F30 -> 19.04 | G20: =ROUND((E20*F20),2) -> 2992.9
A21: 11 | B21: анализ 11 | C21: Превоз с ръчни колички на пясък на 50м | D21: м3 | E21: 157.19 | F21: ='Ед. Цени'!F31 -> 6.14 | G21: =ROUND((E21*F21),2) -> 965.15
A22: 12 | B22: анализ 12 | C22: Подложка от пясък 10см. | D22: м3 | E22: 31.438 | F22: ='Ед. Цени'!F32 -> 8.17 | G22: =ROUND((E22*F22),2) -> 256.85
A23: 13 | B23: анализ 13 | C23: Засипване на тръби с пясък - 40см. | D23: м3 | E23: 125.752 | F23: ='Ед. Цени'!F33 -> 4.75 | G23: =ROUND((E23*F23),2) -> 597.32
A24: 14 | B24: анализ 14 | C24: Уплътняване на пясък с пневматична трамбовка | D24: м3 | E24: 157.19 | F24: ='Ед. Цени'!F34 -> 3.66 | G24: =ROUND((E24*F24),2) -> 575.32
A25: 15 | B25: анализ 15 | C25: Доставка на нестандартна скална маса от кариера на 5км | D25: м3 | E25: 251.944 | F25: ='Ед. Цени'!F35 -> 17.82 | G25: =ROUND((E25*F25),2) -> 4489.64
A26: 16 | B26: анализ 16 | C26: Превоз с ръчни колички на скална маса на 50м | D26: м3 | E26: 251.944 | F26: ='Ед. Цени'!F36 -> 6.14 | G26: =ROUND((E26*F26),2) -> 1546.94
... A31: 21 | B31: анализ 21 | C31: Извозване асфалтови отпадъци със самосвал до 5км. | D31: м3 | E31: 39.872 | F31: ='Ед. Цени'!F41 -> 2.3 | G31: =ROUND((E31*F31),2) -> 91.71
A32: 22 | B32: анализ 23 | C32: Полагане ПЕВП тръби ø90мм. | D32: л.м. | E32: 221.8 | F32: ='Ед. Цени'!F43 -> 26.13 | G32: =ROUND((E32*F32),2) -> 5795.63
A33: 23 | B33: анализ 24 | C33: Полагане ПЕВП тръби ø32мм. | D33: л.м. | E33: 64 | F33: ='Ед. Цени'!F44 -> 7.79 | G33: =ROUND((E33*F33),2) -> 498.56
A34: 24 | B34: анализ 25 | C34: БОБ | D34: бр. | E34: 7 | F34: ='Ед. Цени'!F45 -> 14.87 | G34: =ROUND((E34*F34),2) -> 104.09
A35: 25 | B35: Анализ 88 | C35: ВС ф90/1" | D35: бр. | E35: 12 | F35: ='Ед. Цени'!F108 -> 57.71 | G35: =ROUND((E35*F35),2) -> 692.52
A36: 26 | B36: Анализ 89 | C36: Дъга ф90/12 | D36: бр. | E36: 1 | F36: ='Ед. Цени'!F109 -> 41.12 | G36: =ROUND((E36*F36),2) -> 41.12
A37: 27 | B37: анализ 29 | C37: Заварка ф90 | D37: бр. | E37: 31.4 | F37: ='Ед. Цени'!F49 -> 15.4 | G37: =ROUND((E37*F37),2) -> 483.56
A38: 28 | B38: анализ 30 | C38: Ко ф32/1" | D38: бр. | E38: 12 | F38: ='Ед. Цени'!F50 -> 15.9 | G38: =ROUND((E38*F38),2) -> 190.8
A39: 29 | B39: анализ 31 | C39: ПМ ф32/1" | D39: бр. | E39: 12 | F39: ='Ед. Цени'!F51 -> 18.32 | G39: =ROUND((E39*F39),2) -> 219.84
A40: 30 | B40: анализ 32 | C40: ПП. Фл. ф90 | D40: бр. | E40: 4 | F40: ='Ед. Цени'!F52 -> 35.82 | G40: =ROUND((E40*F40),2) -> 143.28
A41: 31 | B41: анализ 33 | C41: ПХ ф70/80 | D41: бр. | E41: 2 | F41: ='Ед. Цени'!F53 -> 324.5 | G41: =ROUND((E41*F41),2) -> 649
A42: 32 | B42: анализ 34 | C42: Св. Фл. ф80 | D42: бр. | E42: 4 | F42: ='Ед. Цени'!F54 -> 39.45 | G42: =ROUND((E42*F42),2) -> 157.8
A43: 33 | B43: анализ 35 | C43: СК ф80 с охр. гарн. | D43: бр. | E43: 3 | F43: ='Ед. Цени'!F55 -> 150.7 | G43: =ROUND((E43*F43),2) -> 452.1
A44: 34 | B44: Анализ 85 | C44: Т ф90/ф90 | D44: бр. | E44: 3 | F44: ='Ед. Цени'!F105 -> 53.66 | G44: =ROUND((E44*F44),2) -> 160.98
A45: 35 | B45: анализ 37 | C45: ТСК ф1" | D45: бр. | E45: 12 | F45: ='Ед. Цени'!F57 -> 132.99 | G45: =ROUND((E45*F45),2) -> 1595.88
A46: 36 | B46: анализ 38 | C46: ФС Ф80 | D46: бр. | E46: 4 | F46: ='Ед. Цени'!F58 -> 39.45 | G46: =ROUND((E46*F46),2) -> 157.8
A47: 37 | B47: анализ 39 | C47: Хидравлично изпитване на водопровод | D47: л.м. | E47: 285.8 | F47: ='Ед. Цени'!F59 -> 1.78 | G47: =ROUND((E47*F47),2) -> 508.72
A48: 38 | B48: анализ 40 | C48: Дезинфекция на водопровод | D48: л.м. | E48: 285.8 | F48: ='Ед. Цени'!F60 -> 1.61 | G48: =ROUND((E48*F48),2) -> 460.14
...

Sheet кл.12
A1: Обект: Реконструкция на компрометирани участъци от водопроводната мрежа в с.Апарухово, Общ.Дългопол- етап 2
A2: Възложител: Община Дългопол
A4: KОЛИЧЕСТВЕНО- СТОЙНОСТНА СМЕТКА - Клон 12 /о.т. 127 до о.т.85/
A6: № | C6: Вид СМР | D6: М-ка | E6: Количество | F6: Ед. цена | G6: Стойност
A9: 1 | C9: 2 | D9: 3 | E9: 4 | F9: 5 | G9: 6
A10: I. ЧАСТ ВОДОСНАБДЯВАНЕ
A11: 1 | B11: анализ 1 | C11: Рязане с фугорез на асфалтова настилка | D11: л.м. | E11: 463.6 | F11: ='Ед. Цени'!F21 -> 3.53 | G11: =ROUND((E11*F11),2) -> 1636.51
A12: 2 | B12: анализ 2 | C12: Разваляне асфалтова настилка | D12: м2 | E12: 324.52 | F12: ='Ед. Цени'!F22 -> 6.89 | G12: =ROUND((E12*F12),2) -> 2235.94
A13: 3 | B13: анализ 3 | C13: Изкоп с багер на отвал ЗП неукрепен - спада се от т.4 | D13: м3 | E13: 306.52776 | F13: ='Ед. Цени'!F23 -> 5.5 | G13: =ROUND((E13*F13),2) -> 1685.9
A14: 4 | B14: Анализ 65 | C14: Изкоп с дълб. до 2м. ръчно - 30% от машинния | D14: м3 | E14: 131.36904 | F14: ='Ед. Цени'!F85 -> 24.35 | G14: =ROUND((E14*F14),2) -> 3198.84
A15: 5 | B15: анализ 5 | C15: Прехвърляне на изкопана земна маса на 2,00 м вертикално и хоризонтално | D15: м3 | E15: 131.36904 | F15: ='Ед. Цени'!F25 -> 12.47 | G15: =ROUND((E15*F15),2) -> 1638.17
A16: 6 | B16: анализ 6 | C16: Натоварване излишната пръст с багер на самосвал | D16: м3 | E16: 437.8968 | F16: ='Ед. Цени'!F26 -> 2.79 | G16: =ROUND((E16*F16),2) -> 1221.73
A17: 7 | B17: анализ 7 | C17: Разриване с булдозер на земни маси | D17: м3 | E17: 437.8968 | F17: ='Ед. Цени'!F27 -> 1.98 | G17: =ROUND((E17*F17),2) -> 867.04
A18: 8 | B18: анализ 8 | C18: Превоз на земни маси със самосвал до 5км. | D18: м3 | E18: 437.8968 | F18: ='Ед. Цени'!F28 -> 2.79 | G18: =ROUND((E18*F18),2) -> 1221.73
A19: 9 | B19: анализ 9 | C19: Неплътно укрепване и разкрепване на изкопи | D19: м2 | E19: 792.756 | F19: ='Ед. Цени'!F29 -> 2.42 | G19: =ROUND((E19*F19),2) -> 1918.47
A20: 10 | B20: анализ 10 | C20: Доставка на пясък със самосвал на 10км. | D20: м3 | E20: 128.04 | F20: ='Ед. Цени'!F30 -> 19.04 | G20: =ROUND((E20*F20),2) -> 2437.88
A21: 11 | B21: анализ 11 | C21: Превоз с ръчни колички на пясък на 50м | D21: м3 | E21: 128.04 | F21: ='Ед. Цени'!F31 -> 6.14 | G21: =ROUND((E21*F21),2) -> 786.17
A22: 12 | B22: анализ 12 | C22: Подложка от пясък 10см. | D22: м3 | E22: 25.608 | F22: ='Ед. Цени'!F32 -> 8.17 | G22: =ROUND((E22*F22),2) -> 209.22
A23: 13 | B23: анализ 13 | C23: Засипване на тръби с пясък - 40см. | D23: м3 | E23: 102.432 | F23: ='Ед. Цени'!F33 -> 4.75 | G23: =ROUND((E23*F23),2) -> 486.55
A24: 14 | B24: анализ 14 | C24: Уплътняване на пясък с пневматична трамбовка | D24: м3 | E24: 128.04 | F24: ='Ед. Цени'!F34 -> 3.66 | G24: =ROUND((E24*F24),2) -> 468.63
A25: 15 | B25: анализ 15 | C25: Доставка на нестандартна скална маса от кариера на 5км | D25: м3 | E25: 207.8648 | F25: ='Ед. Цени'!F35 -> 17.82 | G25: =ROUND((E25*F25),2) -> 3704.15
A26: 16 | B26: анализ 16 | C26: Превоз с ръчни колички на скална маса на 50м | D26: м3 | E26: 207.8648 | F26: ='Ед. Цени'!F36 -> 6.14 | G26: =ROUND((E26*F26),2) -> 1276.29
... A31: 21 | B31: анализ 21 | C31: Извозване асфалтови отпадъци със самосвал до 5км. | D31: м3 | E31: 32.452 | F31: ='Ед. Цени'!F41 -> 2.3 | G31: =ROUND((E31*F31),2) -> 74.64
A32: 22 | B32: анализ 23 | C32: Полагане ПЕВП тръби ø90мм. | D32: л.м. | E32: 184.8 | F32: ='Ед. Цени'!F43 -> 26.13 | G32: =ROUND((E32*F32),2) -> 4828.82
A33: 23 | B33: анализ 24 | C33: Полагане ПЕВП тръби ø32мм. | D33: л.м. | E33: 48 | F33: ='Ед. Цени'!F44 -> 7.79 | G33: =ROUND((E33*F33),2) -> 373.92
A34: 24 | B34: анализ 25 | C34: БОБ | D34: бр. | E34: 7 | F34: ='Ед. Цени'!F45 -> 14.87 | G34: =ROUND((E34*F34),2) -> 104.09
A35: 25 | B35: Анализ 88 | C35: ВС ф90/1" | D35: бр. | E35: 8 | F35: ='Ед. Цени'!F108 -> 57.71 | G35: =ROUND((E35*F35),2) -> 461.68
A36: 26 | B36: анализ 29 | C36: Заварка ф90 | D36: бр. | E36: 28.316667 | F36: ='Ед. Цени'!F49 -> 15.4 | G36: =ROUND((E36*F36),2) -> 436.08
A37: 27 | B37: анализ 30 | C37: Ко ф32/1" | D37: бр. | E37: 8 | F37: ='Ед. Цени'!F50 -> 15.9 | G37: =ROUND((E37*F37),2) -> 127.2
A38: 28 | B38: Анализ 90 | C38: Коляно ф90/45 | D38: бр. | E38: 1 | F38: ='Ед. Цени'!F110 -> 43.54 | G38: =ROUND((E38*F38),2) -> 43.54
A39: 29 | B39: Анализ 82 | C39: Намалител ф110/ф90 | D39: бр. | E39: 1 | F39: ='Ед. Цени'!F102 -> 31.44 | G39: =ROUND((E39*F39),2) -> 31.44
A40: 30 | B40: анализ 31 | C40: ПМ ф32/1" | D40: бр. | E40: 8 | F40: ='Ед. Цени'!F51 -> 18.32 | G40: =ROUND((E40*F40),2) -> 146.56
A41: 31 | B41: анализ 32 | C41: ПП. Фл. ф90 | D41: бр. | E41: 4 | F41: ='Ед. Цени'!F52 -> 35.82 | G41: =ROUND((E41*F41),2) -> 143.28
A42: 32 | B42: анализ 33 | C42: ПХ ф70/80 | D42: бр. | E42: 2 | F42: ='Ед. Цени'!F53 -> 324.5 | G42: =ROUND((E42*F42),2) -> 649
A43: 33 | B43: анализ 34 | C43: Св. Фл. ф80 | D43: бр. | E43: 4 | F43: ='Ед. Цени'!F54 -> 39.45 | G43: =ROUND((E43*F43),2) -> 157.8
A44: 34 | B44: анализ 35 | C44: СК ф80 с охр. гарн. | D44: бр. | E44: 3 | F44: ='Ед. Цени'!F55 -> 150.7 | G44: =ROUND((E44*F44),2) -> 452.1
A45: 35 | B45: Анализ 85 | C45: Т ф90/ф90 | D45: бр. | E45: 3 | F45: ='Ед. Цени'!F105 -> 53.66 | G45: =ROUND((E45*F45),2) -> 160.98
A46: 36 | B46: анализ 37 | C46: ТСК ф1" | D46: бр. | E46: 8 | F46: ='Ед. Цени'!F57 -> 132.99 | G46: =ROUND((E46*F46),2) -> 1063.92
A47: 37 | B47: анализ 38 | C47: ФС Ф80 | D47: бр. | E47: 4 | F47: ='Ед. Цени'!F58 -> 39.45 | G47: =ROUND((E47*F47),2) -> 157.8
A48: 38 | B48: анализ 39 | C48: Хидравлично изпитване на водопровод | D48: л.м. | E48: 232.8 | F48: ='Ед. Цени'!F59 -> 1.78 | G48: =ROUND((E48*F48),2) -> 414.38
...

Sheet кл.15
A1: Обект: Реконструкция на компрометирани участъци от водопроводната мрежа в с.Апарухово, Общ.Дългопол- етап 2
A2: Възложител: Община Дългопол
A4: KОЛИЧЕСТВЕНО- СТОЙНОСТНА СМЕТКА - Клон 15 /о.т. 84 до о.т.85/
A6: № | C6: Вид СМР | D6: М-ка | E6: Количество | F6: Ед. цена | G6: Стойност
A9: 1 | C9: 2 | D9: 3 | E9: 4 | F9: 5 | G9: 6
A10: I. ЧАСТ ВОДОСНАБДЯВАНЕ
A11: 1 | B11: анализ 1 | C11: Рязане с фугорез на асфалтова настилка | D11: л.м. | E11: 319.8 | F11: ='Ед. Цени'!F21 -> 3.53 | G11: =ROUND((E11*F11),2) -> 1128.89
A12: 2 | B12: анализ 2 | C12: Разваляне асфалтова настилка | D12: м2 | E12: 223.86 | F12: ='Ед. Цени'!F22 -> 6.89 | G12: =ROUND((E12*F12),2) -> 1542.4
A13: 3 | B13: анализ 3 | C13: Изкоп с багер на отвал ЗП неукрепен - спада се от т.4 | D13: м3 | E13: 209.9636 | F13: ='Ед. Цени'!F23 -> 5.5 | G13: =ROUND((E13*F13),2) -> 1154.8
A14: 4 | B14: Анализ 65 | C14: Изкоп с дълб. до 2м. ръчно - 30% от машинния | D14: м3 | E14: 89.9844 | F14: ='Ед. Цени'!F85 -> 24.35 | G14: =ROUND((E14*F14),2) -> 2191.12
A15: 5 | B15: анализ 5 | C15: Прехвърляне на изкопана земна маса на 2,00 м вертикално и хоризонтално | D15: м3 | E15: 89.9844 | F15: ='Ед. Цени'!F25 -> 12.47 | G15: =ROUND((E15*F15),2) -> 1122.11
A16: 6 | B16: анализ 6 | C16: Натоварване излишната пръст с багер на самосвал | D16: м3 | E16: 299.948 | F16: ='Ед. Цени'!F26 -> 2.79 | G16: =ROUND((E16*F16),2) -> 836.85
A17: 7 | B17: анализ 7 | C17: Разриване с булдозер на земни маси | D17: м3 | E17: 299.948 | F17: ='Ед. Цени'!F27 -> 1.98 | G17: =ROUND((E17*F17),2) -> 593.9
A18: 8 | B18: анализ 8 | C18: Превоз на земни маси със самосвал до 5км. | D18: м3 | E18: 299.948 | F18: ='Ед. Цени'!F28 -> 2.79 | G18: =ROUND((E18*F18),2) -> 836.85
A19: 9 | B19: анализ 9 | C19: Неплътно укрепване и разкрепване на изкопи | D19: м2 | E19: 543.66 | F19: ='Ед. Цени'!F29 -> 2.42 | G19: =ROUND((E19*F19),2) -> 1315.66
A20: 10 | B20: анализ 10 | C20: Доставка на пясък със самосвал на 10км. | D20: м3 | E20: 88.22 | F20: ='Ед. Цени'!F30 -> 19.04 | G20: =ROUND((E20*F20),2) -> 1679.71
A21: 11 | B21: анализ 11 | C21: Превоз с ръчни колички на пясък на 50м | D21: м3 | E21: 88.22 | F21: ='Ед. Цени'!F31 -> 6.14 | G21: =ROUND((E21*F21),2) -> 541.67
A22: 12 | B22: анализ 12 | C22: Подложка от пясък 10см. | D22: м3 | E22: 17.644 | F22: ='Ед. Цени'!F32 -> 8.17 | G22: =ROUND((E22*F22),2) -> 144.15
A23: 13 | B23: анализ 13 | C23: Засипване на тръби с пясък - 40см. | D23: м3 | E23: 70.576 | F23: ='Ед. Цени'!F33 -> 4.75 | G23: =ROUND((E23*F23),2) -> 335.24
A24: 14 | B24: анализ 14 | C24: Уплътняване на пясък с пневматична трамбовка | D24: м3 | E24: 88.22 | F24: ='Ед. Цени'!F34 -> 3.66 | G24: =ROUND((E24*F24),2) -> 322.89
A25: 15 | B25: анализ 15 | C25: Доставка на нестандартна скална маса от кариера на 5км | D25: м3 | E25: 141.372 | F25: ='Ед. Цени'!F35 -> 17.82 | G25: =ROUND((E25*F25),2) -> 2519.25
A26: 16 | B26: анализ 16 | C26: Превоз с ръчни колички на скална маса на 50м | D26: м3 | E26: 141.372 | F26: ='Ед. Цени'!F36 -> 6.14 | G26: =ROUND((E26*F26),2) -> 868.02
... A31: 21 | B31: анализ 21 | C31: Извозване асфалтови отпадъци със самосвал до 5км. | D31: м3 | E31: 22.386 | F31: ='Ед. Цени'!F41 -> 2.3 | G31: =ROUND((E31*F31),2) -> 51.49
A32: 22 | B32: анализ 23 | C32: Полагане ПЕВП тръби ø90мм. | D32: л.м. | E32: 152.4 | F32: ='Ед. Цени'!F43 -> 26.13 | G32: =ROUND((E32*F32),2) -> 3982.21
A33: 23 | B33: Анализ 91 | C33: Полагане ПЕВП тръби ø63мм. | D33: л.м. | E33: 8 | F33: ='Ед. Цени'!F111 -> 8.64 | G33: =ROUND((E33*F33),2) -> 69.12
A34: 24 | B34: Анализ 92 | C34: Дъга ф90/42 | D34: бр. | E34: 1 | F34: ='Ед. Цени'!F112 -> 43.54 | G34: =ROUND((E34*F34),2) -> 43.54
A35: 25 | B35: анализ 25 | C35: БОБ | D35: бр. | E35: 3 | F35: ='Ед. Цени'!F45 -> 14.87 | G35: =ROUND((E35*F35),2) -> 44.61
A36: 26 | B36: Анализ 93 | C36: ВС ф90/2" | D36: бр. | E36: 1 | F36: ='Ед. Цени'!F113 -> 61.34 | G36: =ROUND((E36*F36),2) -> 61.34
A37: 27 | B37: анализ 29 | C37: Заварка ф90 | D37: бр. | E37: 18.158333 | F37: ='Ед. Цени'!F49 -> 15.4 | G37: =ROUND((E37*F37),2) -> 279.64
A38: 28 | B38: Анализ 94 | C38: Ко ф63/2" | D38: бр. | E38: 1 | F38: ='Ед. Цени'!F114 -> 17.3 | G38: =ROUND((E38*F38),2) -> 17.3
A39: 29 | B39: Анализ 95 | C39: ПМ ф63/2" | D39: бр. | E39: 1 | F39: ='Ед. Цени'!F115 -> 19.6 | G39: =ROUND((E39*F39),2) -> 19.6
A40: 30 | B40: анализ 32 | C40: ПП. Фл. ф90 | D40: бр. | E40: 1 | F40: ='Ед. Цени'!F52 -> 35.82 | G40: =ROUND((E40*F40),2) -> 35.82
A41: 31 | B41: анализ 33 | C41: ПХ ф70/80 | D41: бр. | E41: 1 | F41: ='Ед. Цени'!F53 -> 324.5 | G41: =ROUND((E41*F41),2) -> 324.5
A42: 32 | B42: анализ 34 | C42: Св. Фл. ф80 | D42: бр. | E42: 1 | F42: ='Ед. Цени'!F54 -> 39.45 | G42: =ROUND((E42*F42),2) -> 39.45
A43: 33 | B43: анализ 35 | C43: СК ф80 с охр. гарн. | D43: бр. | E43: 1 | F43: ='Ед. Цени'!F55 -> 150.7 | G43: =ROUND((E43*F43),2) -> 150.7
A44: 34 | B44: Анализ 85 | C44: Т ф90/ф90 | D44: бр. | E44: 1 | F44: ='Ед. Цени'!F105 -> 53.66 | G44: =ROUND((E44*F44),2) -> 53.66
A45: 35 | B45: Анализ 96 | C45: ТСК ф2" | D45: бр. | E45: 1 | F45: ='Ед. Цени'!F116 -> 136.62 | G45: =ROUND((E45*F45),2) -> 136.62
A46: 36 | B46: анализ 38 | C46: ФС Ф80 | D46: бр. | E46: 1 | F46: ='Ед. Цени'!F58 -> 39.45 | G46: =ROUND((E46*F46),2) -> 39.45
A47: 37 | B47: анализ 39 | C47: Хидравлично изпитване на водопровод | D47: л.м. | E47: 160.4 | F47: ='Ед. Цени'!F59 -> 1.78 | G47: =ROUND((E47*F47),2) -> 285.51
A48: 38 | B48: анализ 40 | C48: Дезинфекция на водопровод | D48: л.м. | E48: 160.4 | F48: ='Ед. Цени'!F60 -> 1.61 | G48: =ROUND((E48*F48),2) -> 258.24
...

Sheet кл.25.1
A1: Обект: Реконструкция на компрометирани участъци от водопроводната мрежа в с.Апарухово, Общ.Дългопол- етап 2
A2: Възложител: Община Дългопол
A4: KОЛИЧЕСТВЕНО- СТОЙНОСТНА СМЕТКА - Клон 25.1 /о.т.40 до о.т.43/
A7: № | C7: Вид СМР | D7: М-ка | E7: Количество | F7: Ед. цена | G7: Стойност
A10: 1 | C10: 2 | D10: 3 | E10: 4 | F10: 5 | G10: 6
A11: I. ЧАСТ ВОДОСНАБДЯВАНЕ
A12: 1 | B12: анализ 1 | C12: Рязане с фугорез на асфалтова настилка | D12: л.м. | E12: 674.8 | F12: ='Ед. Цени'!F21 -> 3.53 | G12: =ROUND((E12*F12),2) -> 2382.04
A13: 2 | B13: анализ 2 | C13: Разваляне асфалтова настилка | D13: м2 | E13: 472.36 | F13: ='Ед. Цени'!F22 -> 6.89 | G13: =ROUND((E13*F13),2) -> 3254.56
A14: 3 | B14: анализ 3 | C14: Изкоп с багер на отвал ЗП неукрепен - спада се от т.4 | D14: м3 | E14: 444.91293 | F14: ='Ед. Цени'!F23 -> 5.5 | G14: =ROUND((E14*F14),2) -> 2447.02
A15: 4 | B15: Анализ 65 | C15: Изкоп с дълб. до 2м. ръчно - 30% от машинния | D15: м3 | E15: 190.67697 | F15: ='Ед. Цени'!F85 -> 24.35 | G15: =ROUND((E15*F15),2) -> 4642.98
A16: 5 | B16: анализ 5 | C16: Прехвърляне на изкопана земна маса на 2,00 м вертикално и хоризонтално | D16: м3 | E16: 190.67697 | F16: ='Ед. Цени'!F25 -> 12.47 | G16: =ROUND((E16*F16),2) -> 2377.74
A17: 6 | B17: анализ 6 | C17: Натоварване излишната пръст с багер на самосвал | D17: м3 | E17: 635.5899 | F17: ='Ед. Цени'!F26 -> 2.79 | G17: =ROUND((E17*F17),2) -> 1773.3
A18: 7 | B18: анализ 7 | C18: Разриване с булдозер на земни маси | D18: м3 | E18: 635.5899 | F18: ='Ед. Цени'!F27 -> 1.98 | G18: =ROUND((E18*F18),2) -> 1258.47
A19: 8 | B19: анализ 8 | C19: Превоз на земни маси със самосвал до 5км. | D19: м3 | E19: 635.5899 | F19: ='Ед. Цени'!F28 -> 2.79 | G19: =ROUND((E19*F19),2) -> 1773.3
A20: 9 | B20: анализ 9 | C20: Неплътно укрепване и разкрепване на изкопи | D20: м2 | E20: 1153.908 | F20: ='Ед. Цени'!F29 -> 2.42 | G20: =ROUND((E20*F20),2) -> 2792.46
A21: 10 | B21: анализ 10 | C21: Доставка на пясък със самосвал на 10км. | D21: м3 | E21: 185.845 | F21: ='Ед. Цени'!F30 -> 19.04 | G21: =ROUND((E21*F21),2) -> 3538.49
A22: 11 | B22: анализ 11 | C22: Превоз с ръчни колички на пясък на 50м | D22: м3 | E22: 185.845 | F22: ='Ед. Цени'!F31 -> 6.14 | G22: =ROUND((E22*F22),2) -> 1141.09
A23: 12 | B23: анализ 12 | C23: Подложка от пясък 10см. | D23: м3 | E23: 37.169 | F23: ='Ед. Цени'!F32 -> 8.17 | G23: =ROUND((E23*F23),2) -> 303.67
A24: 13 | B24: анализ 13 | C24: Засипване на тръби с пясък - 40см. | D24: м3 | E24: 148.676 | F24: ='Ед. Цени'!F33 -> 4.75 | G24: =ROUND((E24*F24),2) -> 706.21
A25: 14 | B25: анализ 14 | C25: Уплътняване на пясък с пневматична трамбовка | D25: м3 | E25: 185.845 | F25: ='Ед. Цени'!F34 -> 3.66 | G25: =ROUND((E25*F25),2) -> 680.19
A26: 15 | B26: анализ 15 | C26: Доставка на нестандартна скална маса от кариера на 5км | D26: м3 | E26: 301.2889 | F26: ='Ед. Цени'!F35 -> 17.82 | G26: =ROUND((E26*F26),2) -> 5368.97
A27: 16 | B27: анализ 16 | C27: Превоз с ръчни колички на скална маса на 50м | D27: м3 | E27: 301.2889 | F27: ='Ед. Цени'!F36 -> 6.14 | G27: =ROUND((E27*F27),2) -> 1849.91
... A32: 21 | B32: анализ 21 | C32: Извозване асфалтови отпадъци със самосвал до 5км. | D32: м3 | E32: 47.236 | F32: ='Ед. Цени'!F41 -> 2.3 | G32: =ROUND((E32*F32),2) -> 108.64
A33: 22 | B33: анализ 23 | C33: Полагане ПЕВП тръби ø90мм. | D33: л.м. | E33: 251.9 | F33: ='Ед. Цени'!F43 -> 26.13 | G33: =ROUND((E33*F33),2) -> 6582.15
A34: 23 | B34: анализ 24 | C34: Полагане ПЕВП тръби ø32мм. | D34: л.м. | E34: 86 | F34: ='Ед. Цени'!F44 -> 7.79 | G34: =ROUND((E34*F34),2) -> 669.94
A35: 24 | B35: Анализ 97 | C35: Дъга ф90/21 | D35: бр. | E35: 1 | F35: ='Ед. Цени'!F117 -> 42.09 | G35: =ROUND((E35*F35),2) -> 42.09
A36: 25 | B36: анализ 25 | C36: БОБ | D36: бр. | E36: 6 | F36: ='Ед. Цени'!F45 -> 14.87 | G36: =ROUND((E36*F36),2) -> 89.22
A37: 26 | B37: Анализ 88 | C37: ВС ф90/1" | D37: бр. | E37: 18 | F37: ='Ед. Цени'!F108 -> 57.71 | G37: =ROUND((E37*F37),2) -> 1038.78
A38: 27 | B38: Анализ 98 | C38: Дъга ф90/24 | D38: бр. | E38: 1 | F38: ='Ед. Цени'!F118 -> 42.69 | G38: =ROUND((E38*F38),2) -> 42.69
A39: 28 | B39: анализ 29 | C39: Заварка ф90 | D39: бр. | E39: 32.45 | F39: ='Ед. Цени'!F49 -> 15.4 | G39: =ROUND((E39*F39),2) -> 499.73
A40: 29 | B40: анализ 30 | C40: Ко ф32/1" | D40: бр. | E40: 18 | F40: ='Ед. Цени'!F50 -> 15.9 | G40: =ROUND((E40*F40),2) -> 286.2
A41: 30 | B41: анализ 31 | C41: ПМ ф32/1" | D41: бр. | E41: 18 | F41: ='Ед. Цени'!F51 -> 18.32 | G41: =ROUND((E41*F41),2) -> 329.76
A42: 31 | B42: анализ 32 | C42: ПП. Фл. ф90 | D42: бр. | E42: 3 | F42: ='Ед. Цени'!F52 -> 35.82 | G42: =ROUND((E42*F42),2) -> 107.46
A43: 32 | B43: анализ 33 | C43: ПХ ф70/80 | D43: бр. | E43: 1 | F43: ='Ед. Цени'!F53 -> 324.5 | G43: =ROUND((E43*F43),2) -> 324.5
A44: 33 | B44: анализ 34 | C44: Св. Фл. ф80 | D44: бр. | E44: 3 | F44: ='Ед. Цени'!F54 -> 39.45 | G44: =ROUND((E44*F44),2) -> 118.35
A45: 34 | B45: анализ 35 | C45: СК ф80 с охр. гарн. | D45: бр. | E45: 2 | F45: ='Ед. Цени'!F55 -> 150.7 | G45: =ROUND((E45*F45),2) -> 301.4
A46: 35 | B46: Анализ 85 | C46: Т ф90/ф90 | D46: бр. | E46: 2 | F46: ='Ед. Цени'!F105 -> 53.66 | G46: =ROUND((E46*F46),2) -> 107.32
A47: 36 | B47: анализ 37 | C47: ТСК ф1" | D47: бр. | E47: 18 | F47: ='Ед. Цени'!F57 -> 132.99 | G47: =ROUND((E47*F47),2) -> 2393.82
A48: 37 | B48: анализ 38 | C48: ФС Ф80 | D48: бр. | E48: 3 | F48: ='Ед. Цени'!F58 -> 39.45 | G48: =ROUND((E48*F48),2) -> 118.35
A49: 38 | B49: анализ 39 | C49: Хидравлично изпитване на водопровод | D49: л.м. | E49: 337.9 | F49: ='Ед. Цени'!F59 -> 1.78 | G49: =ROUND((E49*F49),2) -> 601.46
...

Sheet кл.25.2
A1: Обект: Реконструкция на компрометирани участъци от водопроводната мрежа в с.Апарухово, Общ.Дългопол- етап 2
A2: Възложител: Община Дългопол
A4: KОЛИЧЕСТВЕНО- СТОЙНОСТНА СМЕТКА - Клон 25.2 /о.т.43 до о.т.61/
A6: № | C6: Вид СМР | D6: М-ка | E6: Количество | F6: Ед. цена | G6: Стойност
A9: 1 | C9: 2 | D9: 3 | E9: 4 | F9: 5 | G9: 6
A10: I. ЧАСТ ВОДОСНАБДЯВАНЕ
A11: 1 | B11: анализ 1 | C11: Рязане с фугорез на асфалтова настилка | D11: л.м. | E11: 297.8 | F11: ='Ед. Цени'!F21 -> 3.53 | G11: =ROUND((E11*F11),2) -> 1051.23
A12: 2 | B12: анализ 2 | C12: Разваляне асфалтова настилка | D12: м2 | E12: 208.46 | F12: ='Ед. Цени'!F22 -> 6.89 | G12: =ROUND((E12*F12),2) -> 1436.29
A13: 3 | B13: анализ 3 | C13: Изкоп с багер на отвал ЗП неукрепен - спада се от т.4 | D13: м3 | E13: 196.71498 | F13: ='Ед. Цени'!F23 -> 5.5 | G13: =ROUND((E13*F13),2) -> 1081.93
A14: 4 | B14: Анализ 65 | C14: Изкоп с дълб. до 2м. ръчно - 30% от машинния | D14: м3 | E14: 84.30642 | F14: ='Ед. Цени'!F85 -> 24.35 | G14: =ROUND((E14*F14),2) -> 2052.86
A15: 5 | B15: анализ 5 | C15: Прехвърляне на изкопана земна маса на 2,00 м вертикално и хоризонтално | D15: м3 | E15: 84.30642 | F15: ='Ед. Цени'!F25 -> 12.47 | G15: =ROUND((E15*F15),2) -> 1051.3
A16: 6 | B16: анализ 6 | C16: Натоварване излишната пръст с багер на самосвал | D16: м3 | E16: 281.0214 | F16: ='Ед. Цени'!F26 -> 2.79 | G16: =ROUND((E16*F16),2) -> 784.05
A17: 7 | B17: анализ 7 | C17: Разриване с булдозер на земни маси | D17: м3 | E17: 281.0214 | F17: ='Ед. Цени'!F27 -> 1.98 | G17: =ROUND((E17*F17),2) -> 556.42
A18: 8 | B18: анализ 8 | C18: Превоз на земни маси със самосвал до 5км. | D18: м3 | E18: 281.0214 | F18: ='Ед. Цени'!F28 -> 2.79 | G18: =ROUND((E18*F18),2) -> 784.05
A19: 9 | B19: анализ 9 | C19: Неплътно укрепване и разкрепване на изкопи | D19: м2 | E19: 509.238 | F19: ='Ед. Цени'!F29 -> 2.42 | G19: =ROUND((E19*F19),2) -> 1232.36
A20: 10 | B20: анализ 10 | C20: Доставка на пясък със самосвал на 10км. | D20: м3 | E20: 79.97 | F20: ='Ед. Цени'!F30 -> 19.04 | G20: =ROUND((E20*F20),2) -> 1522.63
A21: 11 | B21: анализ 11 | C21: Превоз с ръчни колички на пясък на 50м | D21: м3 | E21: 79.97 | F21: ='Ед. Цени'!F31 -> 6.14 | G21: =ROUND((E21*F21),2) -> 491.02
A22: 12 | B22: анализ 12 | C22: Подложка от пясък 10см. | D22: м3 | E22: 15.994 | F22: ='Ед. Цени'!F32 -> 8.17 | G22: =ROUND((E22*F22),2) -> 130.67
A23: 13 | B23: анализ 13 | C23: Засипване на тръби с пясък - 40см. | D23: м3 | E23: 63.976 | F23: ='Ед. Цени'!F33 -> 4.75 | G23: =ROUND((E23*F23),2) -> 303.89
A24: 14 | B24: анализ 14 | C24: Уплътняване на пясък с пневматична трамбовка | D24: м3 | E24: 79.97 | F24: ='Ед. Цени'!F34 -> 3.66 | G24: =ROUND((E24*F24),2) -> 292.69
A25: 15 | B25: анализ 15 | C25: Доставка на нестандартна скална маса от кариера на 5км | D25: м3 | E25: 135.5354 | F25: ='Ед. Цени'!F35 -> 17.82 | G25: =ROUND((E25*F25),2) -> 2415.24
A26: 16 | B26: анализ 16 | C26: Превоз с ръчни колички на скална маса на 50м | D26: м3 | E26: 135.5354 | F26: ='Ед. Цени'!F36 -> 6.14 | G26: =ROUND((E26*F26),2) -> 832.19
... A31: 21 | B31: анализ 21 | C31: Извозване асфалтови отпадъци със самосвал до 5км. | D31: м3 | E31: 20.846 | F31: ='Ед. Цени'!F41 -> 2.3 | G31: =ROUND((E31*F31),2) -> 47.95
A32: 22 | B32: анализ 23 | C32: Полагане ПЕВП тръби ø90мм. | D32: л.м. | E32: 145.4 | F32: ='Ед. Цени'!F43 -> 26.13 | G32: =ROUND((E32*F32),2) -> 3799.3
A33: 23 | B33: анализ 24 | C33: Полагане ПЕВП тръби ø32мм. | D33: л.м. | E33: 4 | F33: ='Ед. Цени'!F44 -> 7.79 | G33: =ROUND((E33*F33),2) -> 31.16
A34: 24 | B34: анализ 25 | C34: БОБ | D34: бр. | E34: 8 | F34: ='Ед. Цени'!F45 -> 14.87 | G34: =ROUND((E34*F34),2) -> 118.96
A35: 25 | B35: Анализ 88 | C35: ВС ф90/1" | D35: бр. | E35: 1 | F35: ='Ед. Цени'!F108 -> 57.71 | G35: =ROUND((E35*F35),2) -> 57.71
A36: 26 | B36: Анализ 99 | C36: Дъга ф90/10 | D36: бр. | E36: 3 | F36: ='Ед. Цени'!F119 -> 40.51 | G36: =ROUND((E36*F36),2) -> 121.53
A37: 27 | B37: Анализ 89 | C37: Дъга ф90/12 | D37: бр. | E37: 1 | F37: ='Ед. Цени'!F109 -> 41.12 | G37: =ROUND((E37*F37),2) -> 41.12
A38: 28 | B38: анализ 29 | C38: Заварка ф90 | D38: бр. | E38: 26.575 | F38: ='Ед. Цени'!F49 -> 15.4 | G38: =ROUND((E38*F38),2) -> 409.26
A39: 29 | B39: анализ 30 | C39: Ко ф32/1" | D39: бр. | E39: 1 | F39: ='Ед. Цени'!F50 -> 15.9 | G39: =ROUND((E39*F39),2) -> 15.9
A40: 30 | B40: анализ 31 | C40: ПМ ф32/1" | D40: бр. | E40: 1 | F40: ='Ед. Цени'!F51 -> 18.32 | G40: =ROUND((E40*F40),2) -> 18.32
A41: 31 | B41: анализ 32 | C41: ПП. Фл. ф90 | D41: бр. | E41: 3 | F41: ='Ед. Цени'!F52 -> 35.82 | G41: =ROUND((E41*F41),2) -> 107.46
A42: 32 | B42: анализ 33 | C42: ПХ ф70/80 | D42: бр. | E42: 1 | F42: ='Ед. Цени'!F53 -> 324.5 | G42: =ROUND((E42*F42),2) -> 324.5
A43: 33 | B43: анализ 34 | C43: Св. Фл. ф80 | D43: бр. | E43: 3 | F43: ='Ед. Цени'!F54 -> 39.45 | G43: =ROUND((E43*F43),2) -> 118.35
